[Mon Mar 30 16:09:59.643424 2020] [mpm_event:notice] [pid 44134:tid 140381694175104] AH00489: Apache/2.4.18 (Ubuntu) configured -- resuming normal operations
[Mon Mar 30 16:09:59.643581 2020] [core:notice] [pid 44134:tid 140381694175104] AH00094: Command line: '/usr/sbin/apache2'
[Mon Mar 30 16:11:06.113418 2020] [mpm_event:notice] [pid 44134:tid 140381694175104] AH00491: caught SIGTERM, shutting down
[Mon Mar 30 16:11:07.318535 2020] [mpm_prefork:notice] [pid 50968] AH00163: Apache/2.4.18 (Ubuntu) configured -- resuming normal operations
[Mon Mar 30 16:11:07.318737 2020] [core:notice] [pid 50968] AH00094: Command line: '/usr/sbin/apache2'
[Mon Mar 30 16:11:09.086841 2020] [mpm_prefork:notice] [pid 50968] AH00169: caught SIGTERM, shutting down
[Mon Mar 30 16:11:10.371000 2020] [mpm_prefork:notice] [pid 51082] AH00163: Apache/2.4.18 (Ubuntu) configured -- resuming normal operations
[Mon Mar 30 16:11:10.371112 2020] [core:notice] [pid 51082] AH00094: Command line: '/usr/sbin/apache2'
[Mon Mar 30 16:11:18.816966 2020] [mpm_prefork:notice] [pid 51082] AH00169: caught SIGTERM, shutting down
[Mon Mar 30 16:11:20.055218 2020] [mpm_prefork:notice] [pid 51184] AH00163: Apache/2.4.18 (Ubuntu) configured -- resuming normal operations
[Mon Mar 30 16:11:20.055299 2020] [core:notice] [pid 51184] AH00094: Command line: '/usr/sbin/apache2'
[Mon Mar 30 16:28:34.299075 2020] [mpm_prefork:notice] [pid 51184] AH00169: caught SIGTERM, shutting down
[Mon Mar 30 16:28:35.495288 2020] [mpm_prefork:notice] [pid 57963] AH00163: Apache/2.4.18 (Ubuntu) mod_wsgi/4.3.0 Python/2.7.12 configured -- resuming normal operations
[Mon Mar 30 16:28:35.495380 2020] [core:notice] [pid 57963] AH00094: Command line: '/usr/sbin/apache2'
[Mon Mar 30 16:59:59.887154 2020] [mpm_prefork:notice] [pid 57963] AH00169: caught SIGTERM, shutting down
[Mon Mar 30 17:00:01.189474 2020] [mpm_prefork:notice] [pid 61582] AH00163: Apache/2.4.18 (Ubuntu) mod_wsgi/4.3.0 Python/2.7.12 configured -- resuming normal operations
[Mon Mar 30 17:00:01.189612 2020] [core:notice] [pid 61582] AH00094: Command line: '/usr/sbin/apache2'
[Mon Mar 30 17:06:31.283260 2020] [mpm_prefork:notice] [pid 61582] AH00169: caught SIGTERM, shutting down
[Mon Mar 30 17:06:32.529610 2020] [mpm_prefork:notice] [pid 62176] AH00163: Apache/2.4.18 (Ubuntu) mod_wsgi/4.3.0 Python/2.7.12 configured -- resuming normal operations
[Mon Mar 30 17:06:32.529721 2020] [core:notice] [pid 62176] AH00094: Command line: '/usr/sbin/apache2'
[Mon Mar 30 17:39:06.243194 2020] [wsgi:error] [pid 62181] [client 39.57.186.42:61616] mod_wsgi (pid=62181): Target WSGI script '/var/www/FlaskApp/flaskapp.wsgi' cannot be loaded as Python module.
[Mon Mar 30 17:39:06.243271 2020] [wsgi:error] [pid 62181] [client 39.57.186.42:61616] mod_wsgi (pid=62181): Exception occurred processing WSGI script '/var/www/FlaskApp/flaskapp.wsgi'.
[Mon Mar 30 17:39:06.243337 2020] [wsgi:error] [pid 62181] [client 39.57.186.42:61616] Traceback (most recent call last):
[Mon Mar 30 17:39:06.243386 2020] [wsgi:error] [pid 62181] [client 39.57.186.42:61616]   File "/var/www/FlaskApp/flaskapp.wsgi", line 7, in <module>
[Mon Mar 30 17:39:06.243504 2020] [wsgi:error] [pid 62181] [client 39.57.186.42:61616]     from FlaskApp import app as application
[Mon Mar 30 17:39:06.243532 2020] [wsgi:error] [pid 62181] [client 39.57.186.42:61616]   File "/var/www/FlaskApp/FlaskApp/__init__.py", line 5, in <module>
[Mon Mar 30 17:39:06.243649 2020] [wsgi:error] [pid 62181] [client 39.57.186.42:61616]     from werkzeug import secure_filename
[Mon Mar 30 17:39:06.243688 2020] [wsgi:error] [pid 62181] [client 39.57.186.42:61616] ImportError: cannot import name secure_filename
[Mon Mar 30 17:47:20.194957 2020] [wsgi:error] [pid 62246] [client 39.57.186.42:61697] mod_wsgi (pid=62246): Target WSGI script '/var/www/FlaskApp/flaskapp.wsgi' cannot be loaded as Python module.
[Mon Mar 30 17:47:20.195029 2020] [wsgi:error] [pid 62246] [client 39.57.186.42:61697] mod_wsgi (pid=62246): Exception occurred processing WSGI script '/var/www/FlaskApp/flaskapp.wsgi'.
[Mon Mar 30 17:47:20.195087 2020] [wsgi:error] [pid 62246] [client 39.57.186.42:61697] Traceback (most recent call last):
[Mon Mar 30 17:47:20.195159 2020] [wsgi:error] [pid 62246] [client 39.57.186.42:61697]   File "/var/www/FlaskApp/flaskapp.wsgi", line 7, in <module>
[Mon Mar 30 17:47:20.195284 2020] [wsgi:error] [pid 62246] [client 39.57.186.42:61697]     from FlaskApp import app as application
[Mon Mar 30 17:47:20.195312 2020] [wsgi:error] [pid 62246] [client 39.57.186.42:61697]   File "/var/www/FlaskApp/FlaskApp/__init__.py", line 7, in <module>
[Mon Mar 30 17:47:20.195435 2020] [wsgi:error] [pid 62246] [client 39.57.186.42:61697]     import html
[Mon Mar 30 17:47:20.195482 2020] [wsgi:error] [pid 62246] [client 39.57.186.42:61697] ImportError: No module named html
[Mon Mar 30 17:47:35.752389 2020] [wsgi:error] [pid 62182] [client 39.57.186.42:61700] mod_wsgi (pid=62182): Target WSGI script '/var/www/FlaskApp/flaskapp.wsgi' cannot be loaded as Python module.
[Mon Mar 30 17:47:35.752494 2020] [wsgi:error] [pid 62182] [client 39.57.186.42:61700] mod_wsgi (pid=62182): Exception occurred processing WSGI script '/var/www/FlaskApp/flaskapp.wsgi'.
[Mon Mar 30 17:47:35.752564 2020] [wsgi:error] [pid 62182] [client 39.57.186.42:61700] Traceback (most recent call last):
[Mon Mar 30 17:47:35.752721 2020] [wsgi:error] [pid 62182] [client 39.57.186.42:61700]   File "/var/www/FlaskApp/flaskapp.wsgi", line 7, in <module>
[Mon Mar 30 17:47:35.752832 2020] [wsgi:error] [pid 62182] [client 39.57.186.42:61700]     from FlaskApp import app as application
[Mon Mar 30 17:47:35.752854 2020] [wsgi:error] [pid 62182] [client 39.57.186.42:61700]   File "/var/www/FlaskApp/FlaskApp/__init__.py", line 7, in <module>
[Mon Mar 30 17:47:35.752973 2020] [wsgi:error] [pid 62182] [client 39.57.186.42:61700]     import html
[Mon Mar 30 17:47:35.753012 2020] [wsgi:error] [pid 62182] [client 39.57.186.42:61700] ImportError: No module named html
[Mon Mar 30 17:47:45.434766 2020] [wsgi:error] [pid 62181] [client 39.57.186.42:61701] mod_wsgi (pid=62181): Target WSGI script '/var/www/FlaskApp/flaskapp.wsgi' cannot be loaded as Python module.
[Mon Mar 30 17:47:45.434818 2020] [wsgi:error] [pid 62181] [client 39.57.186.42:61701] mod_wsgi (pid=62181): Exception occurred processing WSGI script '/var/www/FlaskApp/flaskapp.wsgi'.
[Mon Mar 30 17:47:45.434857 2020] [wsgi:error] [pid 62181] [client 39.57.186.42:61701] Traceback (most recent call last):
[Mon Mar 30 17:47:45.434906 2020] [wsgi:error] [pid 62181] [client 39.57.186.42:61701]   File "/var/www/FlaskApp/flaskapp.wsgi", line 7, in <module>
[Mon Mar 30 17:47:45.434969 2020] [wsgi:error] [pid 62181] [client 39.57.186.42:61701]     from FlaskApp import app as application
[Mon Mar 30 17:47:45.434990 2020] [wsgi:error] [pid 62181] [client 39.57.186.42:61701]   File "/var/www/FlaskApp/FlaskApp/__init__.py", line 7, in <module>
[Mon Mar 30 17:47:45.435183 2020] [wsgi:error] [pid 62181] [client 39.57.186.42:61701]     import html
[Mon Mar 30 17:47:45.435222 2020] [wsgi:error] [pid 62181] [client 39.57.186.42:61701] ImportError: No module named html
[Mon Mar 30 18:28:27.782084 2020] [wsgi:error] [pid 62251] [client 39.57.186.42:61837] mod_wsgi (pid=62251): Target WSGI script '/var/www/FlaskApp/flaskapp.wsgi' cannot be loaded as Python module.
[Mon Mar 30 18:28:27.782161 2020] [wsgi:error] [pid 62251] [client 39.57.186.42:61837] mod_wsgi (pid=62251): Exception occurred processing WSGI script '/var/www/FlaskApp/flaskapp.wsgi'.
[Mon Mar 30 18:28:27.782221 2020] [wsgi:error] [pid 62251] [client 39.57.186.42:61837] Traceback (most recent call last):
[Mon Mar 30 18:28:27.782263 2020] [wsgi:error] [pid 62251] [client 39.57.186.42:61837]   File "/var/www/FlaskApp/flaskapp.wsgi", line 7, in <module>
[Mon Mar 30 18:28:27.782391 2020] [wsgi:error] [pid 62251] [client 39.57.186.42:61837]     from FlaskApp import app as application
[Mon Mar 30 18:28:27.782416 2020] [wsgi:error] [pid 62251] [client 39.57.186.42:61837]   File "/var/www/FlaskApp/FlaskApp/__init__.py", line 7, in <module>
[Mon Mar 30 18:28:27.782538 2020] [wsgi:error] [pid 62251] [client 39.57.186.42:61837]     import html
[Mon Mar 30 18:28:27.782597 2020] [wsgi:error] [pid 62251] [client 39.57.186.42:61837] ImportError: No module named html
[Mon Mar 30 18:28:30.665427 2020] [wsgi:error] [pid 62182] [client 39.57.186.42:61838] mod_wsgi (pid=62182): Target WSGI script '/var/www/FlaskApp/flaskapp.wsgi' cannot be loaded as Python module.
[Mon Mar 30 18:28:30.665510 2020] [wsgi:error] [pid 62182] [client 39.57.186.42:61838] mod_wsgi (pid=62182): Exception occurred processing WSGI script '/var/www/FlaskApp/flaskapp.wsgi'.
[Mon Mar 30 18:28:30.665584 2020] [wsgi:error] [pid 62182] [client 39.57.186.42:61838] Traceback (most recent call last):
[Mon Mar 30 18:28:30.665632 2020] [wsgi:error] [pid 62182] [client 39.57.186.42:61838]   File "/var/www/FlaskApp/flaskapp.wsgi", line 7, in <module>
[Mon Mar 30 18:28:30.665723 2020] [wsgi:error] [pid 62182] [client 39.57.186.42:61838]     from FlaskApp import app as application
[Mon Mar 30 18:28:30.665760 2020] [wsgi:error] [pid 62182] [client 39.57.186.42:61838]   File "/var/www/FlaskApp/FlaskApp/__init__.py", line 7, in <module>
[Mon Mar 30 18:28:30.665803 2020] [wsgi:error] [pid 62182] [client 39.57.186.42:61838]     import html
[Mon Mar 30 18:28:30.665842 2020] [wsgi:error] [pid 62182] [client 39.57.186.42:61838] ImportError: No module named html
[Mon Mar 30 18:28:35.198243 2020] [wsgi:error] [pid 62181] [client 39.57.186.42:61839] mod_wsgi (pid=62181): Target WSGI script '/var/www/FlaskApp/flaskapp.wsgi' cannot be loaded as Python module.
[Mon Mar 30 18:28:35.198296 2020] [wsgi:error] [pid 62181] [client 39.57.186.42:61839] mod_wsgi (pid=62181): Exception occurred processing WSGI script '/var/www/FlaskApp/flaskapp.wsgi'.
[Mon Mar 30 18:28:35.198333 2020] [wsgi:error] [pid 62181] [client 39.57.186.42:61839] Traceback (most recent call last):
[Mon Mar 30 18:28:35.198373 2020] [wsgi:error] [pid 62181] [client 39.57.186.42:61839]   File "/var/www/FlaskApp/flaskapp.wsgi", line 7, in <module>
[Mon Mar 30 18:28:35.198441 2020] [wsgi:error] [pid 62181] [client 39.57.186.42:61839]     from FlaskApp import app as application
[Mon Mar 30 18:28:35.198473 2020] [wsgi:error] [pid 62181] [client 39.57.186.42:61839]   File "/var/www/FlaskApp/FlaskApp/__init__.py", line 7, in <module>
[Mon Mar 30 18:28:35.198513 2020] [wsgi:error] [pid 62181] [client 39.57.186.42:61839]     import html
[Mon Mar 30 18:28:35.198551 2020] [wsgi:error] [pid 62181] [client 39.57.186.42:61839] ImportError: No module named html
[Mon Mar 30 18:34:43.952057 2020] [mpm_prefork:notice] [pid 62176] AH00171: Graceful restart requested, doing restart
AH00558: apache2: Could not reliably determine the server's fully qualified domain name, using NS1.saadjumani.com. Set the 'ServerName' directive globally to suppress this message
[Mon Mar 30 18:34:44.116475 2020] [mpm_prefork:notice] [pid 62176] AH00163: Apache/2.4.18 (Ubuntu) mod_wsgi/4.3.0 Python/2.7.12 configured -- resuming normal operations
[Mon Mar 30 18:34:44.116542 2020] [core:notice] [pid 62176] AH00094: Command line: '/usr/sbin/apache2'
[Mon Mar 30 18:37:02.675297 2020] [mpm_prefork:notice] [pid 62176] AH00169: caught SIGTERM, shutting down
[Mon Mar 30 18:37:03.925422 2020] [mpm_prefork:notice] [pid 3733] AH00163: Apache/2.4.18 (Ubuntu) mod_wsgi/4.3.0 Python/2.7.12 configured -- resuming normal operations
[Mon Mar 30 18:37:03.925516 2020] [core:notice] [pid 3733] AH00094: Command line: '/usr/sbin/apache2'
[Mon Mar 30 18:37:20.870757 2020] [wsgi:error] [pid 3736] [client 39.57.186.42:61977] mod_wsgi (pid=3736): Target WSGI script '/var/www/FlaskApp/flaskapp.wsgi' cannot be loaded as Python module.
[Mon Mar 30 18:37:20.870842 2020] [wsgi:error] [pid 3736] [client 39.57.186.42:61977] mod_wsgi (pid=3736): Exception occurred processing WSGI script '/var/www/FlaskApp/flaskapp.wsgi'.
[Mon Mar 30 18:37:20.870898 2020] [wsgi:error] [pid 3736] [client 39.57.186.42:61977] Traceback (most recent call last):
[Mon Mar 30 18:37:20.870942 2020] [wsgi:error] [pid 3736] [client 39.57.186.42:61977]   File "/var/www/FlaskApp/flaskapp.wsgi", line 7, in <module>
[Mon Mar 30 18:37:20.871060 2020] [wsgi:error] [pid 3736] [client 39.57.186.42:61977]     from FlaskApp import app as application
[Mon Mar 30 18:37:20.871100 2020] [wsgi:error] [pid 3736] [client 39.57.186.42:61977]   File "/var/www/FlaskApp/FlaskApp/__init__.py", line 7, in <module>
[Mon Mar 30 18:37:20.871219 2020] [wsgi:error] [pid 3736] [client 39.57.186.42:61977]     import html
[Mon Mar 30 18:37:20.871259 2020] [wsgi:error] [pid 3736] [client 39.57.186.42:61977] ImportError: No module named html
[Mon Mar 30 18:37:30.995080 2020] [wsgi:error] [pid 3738] [client 39.57.186.42:61978] mod_wsgi (pid=3738): Target WSGI script '/var/www/FlaskApp/flaskapp.wsgi' cannot be loaded as Python module.
[Mon Mar 30 18:37:30.995163 2020] [wsgi:error] [pid 3738] [client 39.57.186.42:61978] mod_wsgi (pid=3738): Exception occurred processing WSGI script '/var/www/FlaskApp/flaskapp.wsgi'.
[Mon Mar 30 18:37:30.995219 2020] [wsgi:error] [pid 3738] [client 39.57.186.42:61978] Traceback (most recent call last):
[Mon Mar 30 18:37:30.995264 2020] [wsgi:error] [pid 3738] [client 39.57.186.42:61978]   File "/var/www/FlaskApp/flaskapp.wsgi", line 7, in <module>
[Mon Mar 30 18:37:30.995373 2020] [wsgi:error] [pid 3738] [client 39.57.186.42:61978]     from FlaskApp import app as application
[Mon Mar 30 18:37:30.995395 2020] [wsgi:error] [pid 3738] [client 39.57.186.42:61978]   File "/var/www/FlaskApp/FlaskApp/__init__.py", line 7, in <module>
[Mon Mar 30 18:37:30.995513 2020] [wsgi:error] [pid 3738] [client 39.57.186.42:61978]     import html
[Mon Mar 30 18:37:30.995553 2020] [wsgi:error] [pid 3738] [client 39.57.186.42:61978] ImportError: No module named html
[Mon Mar 30 18:37:54.208019 2020] [wsgi:error] [pid 3737] [client 39.57.186.42:61984] mod_wsgi (pid=3737): Target WSGI script '/var/www/FlaskApp/flaskapp.wsgi' cannot be loaded as Python module.
[Mon Mar 30 18:37:54.208100 2020] [wsgi:error] [pid 3737] [client 39.57.186.42:61984] mod_wsgi (pid=3737): Exception occurred processing WSGI script '/var/www/FlaskApp/flaskapp.wsgi'.
[Mon Mar 30 18:37:54.208156 2020] [wsgi:error] [pid 3737] [client 39.57.186.42:61984] Traceback (most recent call last):
[Mon Mar 30 18:37:54.208200 2020] [wsgi:error] [pid 3737] [client 39.57.186.42:61984]   File "/var/www/FlaskApp/flaskapp.wsgi", line 7, in <module>
[Mon Mar 30 18:37:54.208308 2020] [wsgi:error] [pid 3737] [client 39.57.186.42:61984]     from FlaskApp import app as application
[Mon Mar 30 18:37:54.208331 2020] [wsgi:error] [pid 3737] [client 39.57.186.42:61984]   File "/var/www/FlaskApp/FlaskApp/__init__.py", line 7, in <module>
[Mon Mar 30 18:37:54.208447 2020] [wsgi:error] [pid 3737] [client 39.57.186.42:61984]     import html
[Mon Mar 30 18:37:54.208486 2020] [wsgi:error] [pid 3737] [client 39.57.186.42:61984] ImportError: No module named html
[Mon Mar 30 18:38:51.742356 2020] [mpm_prefork:notice] [pid 3733] AH00171: Graceful restart requested, doing restart
AH00558: apache2: Could not reliably determine the server's fully qualified domain name, using NS1.saadjumani.com. Set the 'ServerName' directive globally to suppress this message
[Mon Mar 30 18:38:51.846310 2020] [mpm_prefork:notice] [pid 3733] AH00163: Apache/2.4.18 (Ubuntu) mod_wsgi/4.3.0 Python/2.7.12 configured -- resuming normal operations
[Mon Mar 30 18:38:51.846341 2020] [core:notice] [pid 3733] AH00094: Command line: '/usr/sbin/apache2'
[Mon Mar 30 18:39:19.395391 2020] [wsgi:error] [pid 3864] [client 39.57.186.42:62000] mod_wsgi (pid=3864): Target WSGI script '/var/www/FlaskApp/flaskapp.wsgi' cannot be loaded as Python module.
[Mon Mar 30 18:39:19.395462 2020] [wsgi:error] [pid 3864] [client 39.57.186.42:62000] mod_wsgi (pid=3864): Exception occurred processing WSGI script '/var/www/FlaskApp/flaskapp.wsgi'.
[Mon Mar 30 18:39:19.395529 2020] [wsgi:error] [pid 3864] [client 39.57.186.42:62000] Traceback (most recent call last):
[Mon Mar 30 18:39:19.395574 2020] [wsgi:error] [pid 3864] [client 39.57.186.42:62000]   File "/var/www/FlaskApp/flaskapp.wsgi", line 7, in <module>
[Mon Mar 30 18:39:19.395698 2020] [wsgi:error] [pid 3864] [client 39.57.186.42:62000]     from FlaskApp import app as application
[Mon Mar 30 18:39:19.395741 2020] [wsgi:error] [pid 3864] [client 39.57.186.42:62000]   File "/var/www/FlaskApp/FlaskApp/__init__.py", line 7, in <module>
[Mon Mar 30 18:39:19.395871 2020] [wsgi:error] [pid 3864] [client 39.57.186.42:62000]     import html
[Mon Mar 30 18:39:19.395915 2020] [wsgi:error] [pid 3864] [client 39.57.186.42:62000] ImportError: No module named html
[Mon Mar 30 18:39:21.652657 2020] [wsgi:error] [pid 3866] [client 39.57.186.42:61999] mod_wsgi (pid=3866): Target WSGI script '/var/www/FlaskApp/flaskapp.wsgi' cannot be loaded as Python module.
[Mon Mar 30 18:39:21.652720 2020] [wsgi:error] [pid 3866] [client 39.57.186.42:61999] mod_wsgi (pid=3866): Exception occurred processing WSGI script '/var/www/FlaskApp/flaskapp.wsgi'.
[Mon Mar 30 18:39:21.652780 2020] [wsgi:error] [pid 3866] [client 39.57.186.42:61999] Traceback (most recent call last):
[Mon Mar 30 18:39:21.652820 2020] [wsgi:error] [pid 3866] [client 39.57.186.42:61999]   File "/var/www/FlaskApp/flaskapp.wsgi", line 7, in <module>
[Mon Mar 30 18:39:21.652932 2020] [wsgi:error] [pid 3866] [client 39.57.186.42:61999]     from FlaskApp import app as application
[Mon Mar 30 18:39:21.652954 2020] [wsgi:error] [pid 3866] [client 39.57.186.42:61999]   File "/var/www/FlaskApp/FlaskApp/__init__.py", line 7, in <module>
[Mon Mar 30 18:39:21.653105 2020] [wsgi:error] [pid 3866] [client 39.57.186.42:61999]     import html
[Mon Mar 30 18:39:21.653147 2020] [wsgi:error] [pid 3866] [client 39.57.186.42:61999] ImportError: No module named html
[Mon Mar 30 18:39:25.089695 2020] [wsgi:error] [pid 3865] [client 39.57.186.42:62001] mod_wsgi (pid=3865): Target WSGI script '/var/www/FlaskApp/flaskapp.wsgi' cannot be loaded as Python module.
[Mon Mar 30 18:39:25.089762 2020] [wsgi:error] [pid 3865] [client 39.57.186.42:62001] mod_wsgi (pid=3865): Exception occurred processing WSGI script '/var/www/FlaskApp/flaskapp.wsgi'.
[Mon Mar 30 18:39:25.089830 2020] [wsgi:error] [pid 3865] [client 39.57.186.42:62001] Traceback (most recent call last):
[Mon Mar 30 18:39:25.089872 2020] [wsgi:error] [pid 3865] [client 39.57.186.42:62001]   File "/var/www/FlaskApp/flaskapp.wsgi", line 7, in <module>
[Mon Mar 30 18:39:25.089995 2020] [wsgi:error] [pid 3865] [client 39.57.186.42:62001]     from FlaskApp import app as application
[Mon Mar 30 18:39:25.090021 2020] [wsgi:error] [pid 3865] [client 39.57.186.42:62001]   File "/var/www/FlaskApp/FlaskApp/__init__.py", line 7, in <module>
[Mon Mar 30 18:39:25.090150 2020] [wsgi:error] [pid 3865] [client 39.57.186.42:62001]     import html
[Mon Mar 30 18:39:25.090193 2020] [wsgi:error] [pid 3865] [client 39.57.186.42:62001] ImportError: No module named html
[Mon Mar 30 18:39:31.856865 2020] [wsgi:error] [pid 3867] [client 39.57.186.42:62002] mod_wsgi (pid=3867): Target WSGI script '/var/www/FlaskApp/flaskapp.wsgi' cannot be loaded as Python module.
[Mon Mar 30 18:39:31.856930 2020] [wsgi:error] [pid 3867] [client 39.57.186.42:62002] mod_wsgi (pid=3867): Exception occurred processing WSGI script '/var/www/FlaskApp/flaskapp.wsgi'.
[Mon Mar 30 18:39:31.856990 2020] [wsgi:error] [pid 3867] [client 39.57.186.42:62002] Traceback (most recent call last):
[Mon Mar 30 18:39:31.857055 2020] [wsgi:error] [pid 3867] [client 39.57.186.42:62002]   File "/var/www/FlaskApp/flaskapp.wsgi", line 7, in <module>
[Mon Mar 30 18:39:31.857171 2020] [wsgi:error] [pid 3867] [client 39.57.186.42:62002]     from FlaskApp import app as application
[Mon Mar 30 18:39:31.857194 2020] [wsgi:error] [pid 3867] [client 39.57.186.42:62002]   File "/var/www/FlaskApp/FlaskApp/__init__.py", line 7, in <module>
[Mon Mar 30 18:39:31.857340 2020] [wsgi:error] [pid 3867] [client 39.57.186.42:62002]     import html
[Mon Mar 30 18:39:31.857381 2020] [wsgi:error] [pid 3867] [client 39.57.186.42:62002] ImportError: No module named html
[Mon Mar 30 18:41:47.173066 2020] [wsgi:error] [pid 3864] [client 39.57.186.42:62101] mod_wsgi (pid=3864): Target WSGI script '/var/www/FlaskApp/flaskapp.wsgi' cannot be loaded as Python module.
[Mon Mar 30 18:41:47.173121 2020] [wsgi:error] [pid 3864] [client 39.57.186.42:62101] mod_wsgi (pid=3864): Exception occurred processing WSGI script '/var/www/FlaskApp/flaskapp.wsgi'.
[Mon Mar 30 18:41:47.173172 2020] [wsgi:error] [pid 3864] [client 39.57.186.42:62101] Traceback (most recent call last):
[Mon Mar 30 18:41:47.173213 2020] [wsgi:error] [pid 3864] [client 39.57.186.42:62101]   File "/var/www/FlaskApp/flaskapp.wsgi", line 7, in <module>
[Mon Mar 30 18:41:47.173276 2020] [wsgi:error] [pid 3864] [client 39.57.186.42:62101]     from FlaskApp import app as application
[Mon Mar 30 18:41:47.173345 2020] [wsgi:error] [pid 3864] [client 39.57.186.42:62101]   File "/var/www/FlaskApp/FlaskApp/__init__.py", line 7, in <module>
[Mon Mar 30 18:41:47.173384 2020] [wsgi:error] [pid 3864] [client 39.57.186.42:62101]     import html
[Mon Mar 30 18:41:47.173419 2020] [wsgi:error] [pid 3864] [client 39.57.186.42:62101] ImportError: No module named html
[Mon Mar 30 18:44:26.038174 2020] [wsgi:error] [pid 3865] [client 39.57.186.42:62117] mod_wsgi (pid=3865): Target WSGI script '/var/www/FlaskApp/flaskapp.wsgi' cannot be loaded as Python module.
[Mon Mar 30 18:44:26.038215 2020] [wsgi:error] [pid 3865] [client 39.57.186.42:62117] mod_wsgi (pid=3865): Exception occurred processing WSGI script '/var/www/FlaskApp/flaskapp.wsgi'.
[Mon Mar 30 18:44:26.038252 2020] [wsgi:error] [pid 3865] [client 39.57.186.42:62117] Traceback (most recent call last):
[Mon Mar 30 18:44:26.038290 2020] [wsgi:error] [pid 3865] [client 39.57.186.42:62117]   File "/var/www/FlaskApp/flaskapp.wsgi", line 7, in <module>
[Mon Mar 30 18:44:26.038349 2020] [wsgi:error] [pid 3865] [client 39.57.186.42:62117]     from FlaskApp import app as application
[Mon Mar 30 18:44:26.038370 2020] [wsgi:error] [pid 3865] [client 39.57.186.42:62117]   File "/var/www/FlaskApp/FlaskApp/__init__.py", line 7, in <module>
[Mon Mar 30 18:44:26.038511 2020] [wsgi:error] [pid 3865] [client 39.57.186.42:62117]     import html
[Mon Mar 30 18:44:26.038548 2020] [wsgi:error] [pid 3865] [client 39.57.186.42:62117] ImportError: No module named html
[Mon Mar 30 18:45:09.656459 2020] [wsgi:error] [pid 3864] [client 39.57.186.42:62122] mod_wsgi (pid=3864): Target WSGI script '/var/www/FlaskApp/flaskapp.wsgi' cannot be loaded as Python module.
[Mon Mar 30 18:45:09.656518 2020] [wsgi:error] [pid 3864] [client 39.57.186.42:62122] mod_wsgi (pid=3864): Exception occurred processing WSGI script '/var/www/FlaskApp/flaskapp.wsgi'.
[Mon Mar 30 18:45:09.656571 2020] [wsgi:error] [pid 3864] [client 39.57.186.42:62122] Traceback (most recent call last):
[Mon Mar 30 18:45:09.656629 2020] [wsgi:error] [pid 3864] [client 39.57.186.42:62122]   File "/var/www/FlaskApp/flaskapp.wsgi", line 7, in <module>
[Mon Mar 30 18:45:09.656712 2020] [wsgi:error] [pid 3864] [client 39.57.186.42:62122]     from FlaskApp import app as application
[Mon Mar 30 18:45:09.656743 2020] [wsgi:error] [pid 3864] [client 39.57.186.42:62122]   File "/var/www/FlaskApp/FlaskApp/__init__.py", line 7, in <module>
[Mon Mar 30 18:45:09.656960 2020] [wsgi:error] [pid 3864] [client 39.57.186.42:62122]     import html
[Mon Mar 30 18:45:09.657008 2020] [wsgi:error] [pid 3864] [client 39.57.186.42:62122] ImportError: No module named html
[Mon Mar 30 18:45:14.929830 2020] [wsgi:error] [pid 3866] [client 39.57.186.42:62123] mod_wsgi (pid=3866): Target WSGI script '/var/www/FlaskApp/flaskapp.wsgi' cannot be loaded as Python module.
[Mon Mar 30 18:45:14.929883 2020] [wsgi:error] [pid 3866] [client 39.57.186.42:62123] mod_wsgi (pid=3866): Exception occurred processing WSGI script '/var/www/FlaskApp/flaskapp.wsgi'.
[Mon Mar 30 18:45:14.929921 2020] [wsgi:error] [pid 3866] [client 39.57.186.42:62123] Traceback (most recent call last):
[Mon Mar 30 18:45:14.929963 2020] [wsgi:error] [pid 3866] [client 39.57.186.42:62123]   File "/var/www/FlaskApp/flaskapp.wsgi", line 7, in <module>
[Mon Mar 30 18:45:14.930029 2020] [wsgi:error] [pid 3866] [client 39.57.186.42:62123]     from FlaskApp import app as application
[Mon Mar 30 18:45:14.930052 2020] [wsgi:error] [pid 3866] [client 39.57.186.42:62123]   File "/var/www/FlaskApp/FlaskApp/__init__.py", line 7, in <module>
[Mon Mar 30 18:45:14.930236 2020] [wsgi:error] [pid 3866] [client 39.57.186.42:62123]     import html
[Mon Mar 30 18:45:14.930295 2020] [wsgi:error] [pid 3866] [client 39.57.186.42:62123] ImportError: No module named html
[Mon Mar 30 18:52:46.127484 2020] [wsgi:error] [pid 3867] [client 39.57.186.42:62176] mod_wsgi (pid=3867): Target WSGI script '/var/www/FlaskApp/flaskapp.wsgi' cannot be loaded as Python module.
[Mon Mar 30 18:52:46.127517 2020] [wsgi:error] [pid 3867] [client 39.57.186.42:62176] mod_wsgi (pid=3867): Exception occurred processing WSGI script '/var/www/FlaskApp/flaskapp.wsgi'.
[Mon Mar 30 18:52:46.127552 2020] [wsgi:error] [pid 3867] [client 39.57.186.42:62176] Traceback (most recent call last):
[Mon Mar 30 18:52:46.127591 2020] [wsgi:error] [pid 3867] [client 39.57.186.42:62176]   File "/var/www/FlaskApp/flaskapp.wsgi", line 7, in <module>
[Mon Mar 30 18:52:46.127651 2020] [wsgi:error] [pid 3867] [client 39.57.186.42:62176]     from FlaskApp import app as application
[Mon Mar 30 18:52:46.127672 2020] [wsgi:error] [pid 3867] [client 39.57.186.42:62176]   File "/var/www/FlaskApp/FlaskApp/__init__.py", line 5, in <module>
[Mon Mar 30 18:52:46.127810 2020] [wsgi:error] [pid 3867] [client 39.57.186.42:62176]     from werkzeug import secure_filename
[Mon Mar 30 18:52:46.127865 2020] [wsgi:error] [pid 3867] [client 39.57.186.42:62176] ImportError: cannot import name secure_filename
[Mon Mar 30 18:55:48.555980 2020] [wsgi:error] [pid 3864] [client 39.57.186.42:62207] mod_wsgi (pid=3864): Target WSGI script '/var/www/FlaskApp/flaskapp.wsgi' cannot be loaded as Python module.
[Mon Mar 30 18:55:48.556015 2020] [wsgi:error] [pid 3864] [client 39.57.186.42:62207] mod_wsgi (pid=3864): Exception occurred processing WSGI script '/var/www/FlaskApp/flaskapp.wsgi'.
[Mon Mar 30 18:55:48.556050 2020] [wsgi:error] [pid 3864] [client 39.57.186.42:62207] Traceback (most recent call last):
[Mon Mar 30 18:55:48.556090 2020] [wsgi:error] [pid 3864] [client 39.57.186.42:62207]   File "/var/www/FlaskApp/flaskapp.wsgi", line 7, in <module>
[Mon Mar 30 18:55:48.556142 2020] [wsgi:error] [pid 3864] [client 39.57.186.42:62207]     from FlaskApp import app as application
[Mon Mar 30 18:55:48.556162 2020] [wsgi:error] [pid 3864] [client 39.57.186.42:62207]   File "/var/www/FlaskApp/FlaskApp/__init__.py", line 6, in <module>
[Mon Mar 30 18:55:48.556269 2020] [wsgi:error] [pid 3864] [client 39.57.186.42:62207]     from werkzeug import secure_filename
[Mon Mar 30 18:55:48.556306 2020] [wsgi:error] [pid 3864] [client 39.57.186.42:62207] ImportError: cannot import name secure_filename
[Mon Mar 30 18:59:49.414457 2020] [mpm_prefork:notice] [pid 3733] AH00171: Graceful restart requested, doing restart
AH00558: apache2: Could not reliably determine the server's fully qualified domain name, using NS1.saadjumani.com. Set the 'ServerName' directive globally to suppress this message
[Mon Mar 30 18:59:49.575181 2020] [mpm_prefork:notice] [pid 3733] AH00163: Apache/2.4.18 (Ubuntu) mod_wsgi/4.3.0 Python/2.7.12 configured -- resuming normal operations
[Mon Mar 30 18:59:49.575225 2020] [core:notice] [pid 3733] AH00094: Command line: '/usr/sbin/apache2'
[Mon Mar 30 18:59:52.499924 2020] [wsgi:error] [pid 5722] [client 39.57.186.42:62248] mod_wsgi (pid=5722): Target WSGI script '/var/www/FlaskApp/flaskapp.wsgi' cannot be loaded as Python module.
[Mon Mar 30 18:59:52.499980 2020] [wsgi:error] [pid 5722] [client 39.57.186.42:62248] mod_wsgi (pid=5722): Exception occurred processing WSGI script '/var/www/FlaskApp/flaskapp.wsgi'.
[Mon Mar 30 18:59:52.500040 2020] [wsgi:error] [pid 5722] [client 39.57.186.42:62248] Traceback (most recent call last):
[Mon Mar 30 18:59:52.500073 2020] [wsgi:error] [pid 5722] [client 39.57.186.42:62248]   File "/var/www/FlaskApp/flaskapp.wsgi", line 7, in <module>
[Mon Mar 30 18:59:52.500166 2020] [wsgi:error] [pid 5722] [client 39.57.186.42:62248]     from FlaskApp import app as application
[Mon Mar 30 18:59:52.500198 2020] [wsgi:error] [pid 5722] [client 39.57.186.42:62248] ImportError: No module named FlaskApp
[Mon Mar 30 19:00:27.952202 2020] [wsgi:error] [pid 5723] [client 39.57.186.42:62253] mod_wsgi (pid=5723): Target WSGI script '/var/www/FlaskApp/flaskapp.wsgi' cannot be loaded as Python module.
[Mon Mar 30 19:00:27.952281 2020] [wsgi:error] [pid 5723] [client 39.57.186.42:62253] mod_wsgi (pid=5723): Exception occurred processing WSGI script '/var/www/FlaskApp/flaskapp.wsgi'.
[Mon Mar 30 19:00:27.952363 2020] [wsgi:error] [pid 5723] [client 39.57.186.42:62253] Traceback (most recent call last):
[Mon Mar 30 19:00:27.952418 2020] [wsgi:error] [pid 5723] [client 39.57.186.42:62253]   File "/var/www/FlaskApp/flaskapp.wsgi", line 7, in <module>
[Mon Mar 30 19:00:27.952569 2020] [wsgi:error] [pid 5723] [client 39.57.186.42:62253]     from FlaskApp import app as application
[Mon Mar 30 19:00:27.952706 2020] [wsgi:error] [pid 5723] [client 39.57.186.42:62253]   File "/var/www/FlaskApp/FlaskApp/__init__.py", line 8, in <module>
[Mon Mar 30 19:00:27.952825 2020] [wsgi:error] [pid 5723] [client 39.57.186.42:62253]     import html
[Mon Mar 30 19:00:27.952879 2020] [wsgi:error] [pid 5723] [client 39.57.186.42:62253] ImportError: No module named html
[Mon Mar 30 19:00:32.260057 2020] [wsgi:error] [pid 5720] [client 39.57.186.42:62254] mod_wsgi (pid=5720): Target WSGI script '/var/www/FlaskApp/flaskapp.wsgi' cannot be loaded as Python module.
[Mon Mar 30 19:00:32.260122 2020] [wsgi:error] [pid 5720] [client 39.57.186.42:62254] mod_wsgi (pid=5720): Exception occurred processing WSGI script '/var/www/FlaskApp/flaskapp.wsgi'.
[Mon Mar 30 19:00:32.260190 2020] [wsgi:error] [pid 5720] [client 39.57.186.42:62254] Traceback (most recent call last):
[Mon Mar 30 19:00:32.260234 2020] [wsgi:error] [pid 5720] [client 39.57.186.42:62254]   File "/var/www/FlaskApp/flaskapp.wsgi", line 7, in <module>
[Mon Mar 30 19:00:32.260368 2020] [wsgi:error] [pid 5720] [client 39.57.186.42:62254]     from FlaskApp import app as application
[Mon Mar 30 19:00:32.260393 2020] [wsgi:error] [pid 5720] [client 39.57.186.42:62254]   File "/var/www/FlaskApp/FlaskApp/__init__.py", line 8, in <module>
[Mon Mar 30 19:00:32.260477 2020] [wsgi:error] [pid 5720] [client 39.57.186.42:62254]     import html
[Mon Mar 30 19:00:32.260520 2020] [wsgi:error] [pid 5720] [client 39.57.186.42:62254] ImportError: No module named html
[Mon Mar 30 19:01:06.784107 2020] [wsgi:error] [pid 5722] [client 39.57.186.42:62257] mod_wsgi (pid=5722): Target WSGI script '/var/www/FlaskApp/flaskapp.wsgi' cannot be loaded as Python module.
[Mon Mar 30 19:01:06.784175 2020] [wsgi:error] [pid 5722] [client 39.57.186.42:62257] mod_wsgi (pid=5722): Exception occurred processing WSGI script '/var/www/FlaskApp/flaskapp.wsgi'.
[Mon Mar 30 19:01:06.784231 2020] [wsgi:error] [pid 5722] [client 39.57.186.42:62257] Traceback (most recent call last):
[Mon Mar 30 19:01:06.784277 2020] [wsgi:error] [pid 5722] [client 39.57.186.42:62257]   File "/var/www/FlaskApp/flaskapp.wsgi", line 7, in <module>
[Mon Mar 30 19:01:06.784357 2020] [wsgi:error] [pid 5722] [client 39.57.186.42:62257]     from FlaskApp import app as application
[Mon Mar 30 19:01:06.784378 2020] [wsgi:error] [pid 5722] [client 39.57.186.42:62257]   File "/var/www/FlaskApp/FlaskApp/__init__.py", line 8, in <module>
[Mon Mar 30 19:01:06.784472 2020] [wsgi:error] [pid 5722] [client 39.57.186.42:62257]     import html
[Mon Mar 30 19:01:06.784516 2020] [wsgi:error] [pid 5722] [client 39.57.186.42:62257] ImportError: No module named html
[Mon Mar 30 19:01:37.146618 2020] [mpm_prefork:notice] [pid 3733] AH00171: Graceful restart requested, doing restart
AH00558: apache2: Could not reliably determine the server's fully qualified domain name, using NS1.saadjumani.com. Set the 'ServerName' directive globally to suppress this message
[Mon Mar 30 19:01:37.257064 2020] [mpm_prefork:notice] [pid 3733] AH00163: Apache/2.4.18 (Ubuntu) mod_wsgi/4.3.0 Python/2.7.12 configured -- resuming normal operations
[Mon Mar 30 19:01:37.257125 2020] [core:notice] [pid 3733] AH00094: Command line: '/usr/sbin/apache2'
[Mon Mar 30 19:01:56.466092 2020] [wsgi:error] [pid 5964] [client 39.57.186.42:62260] mod_wsgi (pid=5964): Target WSGI script '/var/www/FlaskApp/flaskapp.wsgi' cannot be loaded as Python module.
[Mon Mar 30 19:01:56.466159 2020] [wsgi:error] [pid 5964] [client 39.57.186.42:62260] mod_wsgi (pid=5964): Exception occurred processing WSGI script '/var/www/FlaskApp/flaskapp.wsgi'.
[Mon Mar 30 19:01:56.466220 2020] [wsgi:error] [pid 5964] [client 39.57.186.42:62260] Traceback (most recent call last):
[Mon Mar 30 19:01:56.466260 2020] [wsgi:error] [pid 5964] [client 39.57.186.42:62260]   File "/var/www/FlaskApp/flaskapp.wsgi", line 7, in <module>
[Mon Mar 30 19:01:56.466373 2020] [wsgi:error] [pid 5964] [client 39.57.186.42:62260]     from FlaskApp import app as application
[Mon Mar 30 19:01:56.466397 2020] [wsgi:error] [pid 5964] [client 39.57.186.42:62260]   File "/var/www/FlaskApp/FlaskApp/__init__.py", line 8, in <module>
[Mon Mar 30 19:01:56.466471 2020] [wsgi:error] [pid 5964] [client 39.57.186.42:62260]     import html
[Mon Mar 30 19:01:56.466512 2020] [wsgi:error] [pid 5964] [client 39.57.186.42:62260] ImportError: No module named html
[Mon Mar 30 19:01:59.706303 2020] [wsgi:error] [pid 5963] [client 39.57.186.42:62259] mod_wsgi (pid=5963): Target WSGI script '/var/www/FlaskApp/flaskapp.wsgi' cannot be loaded as Python module.
[Mon Mar 30 19:01:59.706369 2020] [wsgi:error] [pid 5963] [client 39.57.186.42:62259] mod_wsgi (pid=5963): Exception occurred processing WSGI script '/var/www/FlaskApp/flaskapp.wsgi'.
[Mon Mar 30 19:01:59.706435 2020] [wsgi:error] [pid 5963] [client 39.57.186.42:62259] Traceback (most recent call last):
[Mon Mar 30 19:01:59.706477 2020] [wsgi:error] [pid 5963] [client 39.57.186.42:62259]   File "/var/www/FlaskApp/flaskapp.wsgi", line 7, in <module>
[Mon Mar 30 19:01:59.706610 2020] [wsgi:error] [pid 5963] [client 39.57.186.42:62259]     from FlaskApp import app as application
[Mon Mar 30 19:01:59.706637 2020] [wsgi:error] [pid 5963] [client 39.57.186.42:62259]   File "/var/www/FlaskApp/FlaskApp/__init__.py", line 8, in <module>
[Mon Mar 30 19:01:59.706721 2020] [wsgi:error] [pid 5963] [client 39.57.186.42:62259]     import html
[Mon Mar 30 19:01:59.706763 2020] [wsgi:error] [pid 5963] [client 39.57.186.42:62259] ImportError: No module named html
[Mon Mar 30 19:03:43.495735 2020] [wsgi:error] [pid 5965] [client 39.57.186.42:62271] mod_wsgi (pid=5965): Target WSGI script '/var/www/FlaskApp/flaskapp.wsgi' cannot be loaded as Python module.
[Mon Mar 30 19:03:43.495804 2020] [wsgi:error] [pid 5965] [client 39.57.186.42:62271] mod_wsgi (pid=5965): Exception occurred processing WSGI script '/var/www/FlaskApp/flaskapp.wsgi'.
[Mon Mar 30 19:03:43.495866 2020] [wsgi:error] [pid 5965] [client 39.57.186.42:62271] Traceback (most recent call last):
[Mon Mar 30 19:03:43.495906 2020] [wsgi:error] [pid 5965] [client 39.57.186.42:62271]   File "/var/www/FlaskApp/flaskapp.wsgi", line 7, in <module>
[Mon Mar 30 19:03:43.496020 2020] [wsgi:error] [pid 5965] [client 39.57.186.42:62271]     from FlaskApp import app as application
[Mon Mar 30 19:03:43.496043 2020] [wsgi:error] [pid 5965] [client 39.57.186.42:62271]   File "/var/www/FlaskApp/FlaskApp/__init__.py", line 8, in <module>
[Mon Mar 30 19:03:43.496116 2020] [wsgi:error] [pid 5965] [client 39.57.186.42:62271]     import html
[Mon Mar 30 19:03:43.496155 2020] [wsgi:error] [pid 5965] [client 39.57.186.42:62271] ImportError: No module named html
[Mon Mar 30 19:04:44.083571 2020] [wsgi:error] [pid 5963] [client 39.57.186.42:62278] mod_wsgi (pid=5963): Target WSGI script '/var/www/FlaskApp/flaskapp.wsgi' cannot be loaded as Python module.
[Mon Mar 30 19:04:44.083604 2020] [wsgi:error] [pid 5963] [client 39.57.186.42:62278] mod_wsgi (pid=5963): Exception occurred processing WSGI script '/var/www/FlaskApp/flaskapp.wsgi'.
[Mon Mar 30 19:04:44.083639 2020] [wsgi:error] [pid 5963] [client 39.57.186.42:62278] Traceback (most recent call last):
[Mon Mar 30 19:04:44.083677 2020] [wsgi:error] [pid 5963] [client 39.57.186.42:62278]   File "/var/www/FlaskApp/flaskapp.wsgi", line 7, in <module>
[Mon Mar 30 19:04:44.083746 2020] [wsgi:error] [pid 5963] [client 39.57.186.42:62278]     from FlaskApp import app as application
[Mon Mar 30 19:04:44.083767 2020] [wsgi:error] [pid 5963] [client 39.57.186.42:62278]   File "/var/www/FlaskApp/FlaskApp/__init__.py", line 8, in <module>
[Mon Mar 30 19:04:44.083868 2020] [wsgi:error] [pid 5963] [client 39.57.186.42:62278]     import html
[Mon Mar 30 19:04:44.083904 2020] [wsgi:error] [pid 5963] [client 39.57.186.42:62278] ImportError: No module named html
[Mon Mar 30 19:17:53.593030 2020] [wsgi:error] [pid 5969] [client 51.83.129.245:56474] mod_wsgi (pid=5969): Target WSGI script '/var/www/FlaskApp/flaskapp.wsgi' cannot be loaded as Python module.
[Mon Mar 30 19:17:53.593122 2020] [wsgi:error] [pid 5969] [client 51.83.129.245:56474] mod_wsgi (pid=5969): Exception occurred processing WSGI script '/var/www/FlaskApp/flaskapp.wsgi'.
[Mon Mar 30 19:17:53.593229 2020] [wsgi:error] [pid 5969] [client 51.83.129.245:56474] Traceback (most recent call last):
[Mon Mar 30 19:17:53.593319 2020] [wsgi:error] [pid 5969] [client 51.83.129.245:56474]   File "/var/www/FlaskApp/flaskapp.wsgi", line 7, in <module>
[Mon Mar 30 19:17:53.593524 2020] [wsgi:error] [pid 5969] [client 51.83.129.245:56474]     from FlaskApp import app as application
[Mon Mar 30 19:17:53.593567 2020] [wsgi:error] [pid 5969] [client 51.83.129.245:56474]   File "/var/www/FlaskApp/FlaskApp/__init__.py", line 8, in <module>
[Mon Mar 30 19:17:53.593706 2020] [wsgi:error] [pid 5969] [client 51.83.129.245:56474]     import html
[Mon Mar 30 19:17:53.593773 2020] [wsgi:error] [pid 5969] [client 51.83.129.245:56474] ImportError: No module named html
[Mon Mar 30 19:19:26.283123 2020] [wsgi:error] [pid 5963] [client 39.57.186.42:62435] mod_wsgi (pid=5963): Target WSGI script '/var/www/FlaskApp/flaskapp.wsgi' cannot be loaded as Python module.
[Mon Mar 30 19:19:26.283163 2020] [wsgi:error] [pid 5963] [client 39.57.186.42:62435] mod_wsgi (pid=5963): Exception occurred processing WSGI script '/var/www/FlaskApp/flaskapp.wsgi'.
[Mon Mar 30 19:19:26.283206 2020] [wsgi:error] [pid 5963] [client 39.57.186.42:62435] Traceback (most recent call last):
[Mon Mar 30 19:19:26.283250 2020] [wsgi:error] [pid 5963] [client 39.57.186.42:62435]   File "/var/www/FlaskApp/flaskapp.wsgi", line 7, in <module>
[Mon Mar 30 19:19:26.283329 2020] [wsgi:error] [pid 5963] [client 39.57.186.42:62435]     from FlaskApp import app as application
[Mon Mar 30 19:19:26.283350 2020] [wsgi:error] [pid 5963] [client 39.57.186.42:62435]   File "/var/www/FlaskApp/FlaskApp/__init__.py", line 8, in <module>
[Mon Mar 30 19:19:26.283464 2020] [wsgi:error] [pid 5963] [client 39.57.186.42:62435]     import html
[Mon Mar 30 19:19:26.283502 2020] [wsgi:error] [pid 5963] [client 39.57.186.42:62435] ImportError: No module named html
[Mon Mar 30 19:20:50.595754 2020] [mpm_prefork:notice] [pid 3733] AH00171: Graceful restart requested, doing restart
AH00558: apache2: Could not reliably determine the server's fully qualified domain name, using NS1.saadjumani.com. Set the 'ServerName' directive globally to suppress this message
[Mon Mar 30 19:20:50.716937 2020] [mpm_prefork:notice] [pid 3733] AH00163: Apache/2.4.18 (Ubuntu) mod_wsgi/4.3.0 Python/2.7.12 configured -- resuming normal operations
[Mon Mar 30 19:20:50.716972 2020] [core:notice] [pid 3733] AH00094: Command line: '/usr/sbin/apache2'
[Mon Mar 30 19:20:55.218972 2020] [wsgi:error] [pid 8513] [client 39.57.186.42:62440] mod_wsgi (pid=8513): Target WSGI script '/var/www/FlaskApp/flaskapp.wsgi' cannot be loaded as Python module.
[Mon Mar 30 19:20:55.219037 2020] [wsgi:error] [pid 8513] [client 39.57.186.42:62440] mod_wsgi (pid=8513): Exception occurred processing WSGI script '/var/www/FlaskApp/flaskapp.wsgi'.
[Mon Mar 30 19:20:55.219098 2020] [wsgi:error] [pid 8513] [client 39.57.186.42:62440] Traceback (most recent call last):
[Mon Mar 30 19:20:55.219138 2020] [wsgi:error] [pid 8513] [client 39.57.186.42:62440]   File "/var/www/FlaskApp/flaskapp.wsgi", line 7, in <module>
[Mon Mar 30 19:20:55.219250 2020] [wsgi:error] [pid 8513] [client 39.57.186.42:62440]     from FlaskApp import app as application
[Mon Mar 30 19:20:55.219291 2020] [wsgi:error] [pid 8513] [client 39.57.186.42:62440]   File "/var/www/FlaskApp/FlaskApp/__init__.py", line 8, in <module>
[Mon Mar 30 19:20:55.219402 2020] [wsgi:error] [pid 8513] [client 39.57.186.42:62440]     import html
[Mon Mar 30 19:20:55.219444 2020] [wsgi:error] [pid 8513] [client 39.57.186.42:62440] ImportError: No module named html
[Mon Mar 30 19:21:19.453931 2020] [wsgi:error] [pid 8509] [client 39.57.186.42:62444] mod_wsgi (pid=8509): Target WSGI script '/var/www/FlaskApp/flaskapp.wsgi' cannot be loaded as Python module.
[Mon Mar 30 19:21:19.454015 2020] [wsgi:error] [pid 8509] [client 39.57.186.42:62444] mod_wsgi (pid=8509): Exception occurred processing WSGI script '/var/www/FlaskApp/flaskapp.wsgi'.
[Mon Mar 30 19:21:19.454090 2020] [wsgi:error] [pid 8509] [client 39.57.186.42:62444] Traceback (most recent call last):
[Mon Mar 30 19:21:19.454137 2020] [wsgi:error] [pid 8509] [client 39.57.186.42:62444]   File "/var/www/FlaskApp/flaskapp.wsgi", line 7, in <module>
[Mon Mar 30 19:21:19.454267 2020] [wsgi:error] [pid 8509] [client 39.57.186.42:62444]     from FlaskApp import app as application
[Mon Mar 30 19:21:19.454292 2020] [wsgi:error] [pid 8509] [client 39.57.186.42:62444]   File "/var/www/FlaskApp/FlaskApp/__init__.py", line 8, in <module>
[Mon Mar 30 19:21:19.454376 2020] [wsgi:error] [pid 8509] [client 39.57.186.42:62444]     import html
[Mon Mar 30 19:21:19.454421 2020] [wsgi:error] [pid 8509] [client 39.57.186.42:62444] ImportError: No module named html
[Mon Mar 30 19:21:22.464590 2020] [wsgi:error] [pid 8511] [client 39.57.186.42:62443] mod_wsgi (pid=8511): Target WSGI script '/var/www/FlaskApp/flaskapp.wsgi' cannot be loaded as Python module.
[Mon Mar 30 19:21:22.464680 2020] [wsgi:error] [pid 8511] [client 39.57.186.42:62443] mod_wsgi (pid=8511): Exception occurred processing WSGI script '/var/www/FlaskApp/flaskapp.wsgi'.
[Mon Mar 30 19:21:22.464773 2020] [wsgi:error] [pid 8511] [client 39.57.186.42:62443] Traceback (most recent call last):
[Mon Mar 30 19:21:22.464829 2020] [wsgi:error] [pid 8511] [client 39.57.186.42:62443]   File "/var/www/FlaskApp/flaskapp.wsgi", line 7, in <module>
[Mon Mar 30 19:21:22.465151 2020] [wsgi:error] [pid 8511] [client 39.57.186.42:62443]     from FlaskApp import app as application
[Mon Mar 30 19:21:22.465184 2020] [wsgi:error] [pid 8511] [client 39.57.186.42:62443]   File "/var/www/FlaskApp/FlaskApp/__init__.py", line 8, in <module>
[Mon Mar 30 19:21:22.465387 2020] [wsgi:error] [pid 8511] [client 39.57.186.42:62443] ImportError: No module named html
[Mon Mar 30 19:37:12.456189 2020] [mpm_prefork:notice] [pid 3733] AH00169: caught SIGTERM, shutting down
[Mon Mar 30 19:37:13.560221 2020] [mpm_prefork:notice] [pid 9958] AH00163: Apache/2.4.18 (Ubuntu) mod_wsgi/4.3.0 Python/2.7.12 configured -- resuming normal operations
[Mon Mar 30 19:37:13.560325 2020] [core:notice] [pid 9958] AH00094: Command line: '/usr/sbin/apache2'
[Mon Mar 30 19:38:42.894206 2020] [wsgi:error] [pid 9962] [client 39.57.186.42:62557] mod_wsgi (pid=9962): Target WSGI script '/var/www/FlaskApp/flaskapp.wsgi' cannot be loaded as Python module.
[Mon Mar 30 19:38:42.894290 2020] [wsgi:error] [pid 9962] [client 39.57.186.42:62557] mod_wsgi (pid=9962): Exception occurred processing WSGI script '/var/www/FlaskApp/flaskapp.wsgi'.
[Mon Mar 30 19:38:42.894347 2020] [wsgi:error] [pid 9962] [client 39.57.186.42:62557] Traceback (most recent call last):
[Mon Mar 30 19:38:42.894391 2020] [wsgi:error] [pid 9962] [client 39.57.186.42:62557]   File "/var/www/FlaskApp/flaskapp.wsgi", line 7, in <module>
[Mon Mar 30 19:38:42.894505 2020] [wsgi:error] [pid 9962] [client 39.57.186.42:62557]     from FlaskApp import app as application
[Mon Mar 30 19:38:42.894529 2020] [wsgi:error] [pid 9962] [client 39.57.186.42:62557]   File "/var/www/FlaskApp/FlaskApp/__init__.py", line 8, in <module>
[Mon Mar 30 19:38:42.894602 2020] [wsgi:error] [pid 9962] [client 39.57.186.42:62557]     import html
[Mon Mar 30 19:38:42.894659 2020] [wsgi:error] [pid 9962] [client 39.57.186.42:62557] ImportError: No module named html
[Mon Mar 30 19:56:33.979877 2020] [mpm_prefork:notice] [pid 9958] AH00169: caught SIGTERM, shutting down
[Mon Mar 30 19:56:34.989351 2020] [mpm_prefork:notice] [pid 12251] AH00163: Apache/2.4.18 (Ubuntu) mod_wsgi/4.3.0 Python/3.5.2 configured -- resuming normal operations
[Mon Mar 30 19:56:34.989436 2020] [core:notice] [pid 12251] AH00094: Command line: '/usr/sbin/apache2'
[Mon Mar 30 19:59:42.597175 2020] [wsgi:error] [pid 12258] [client 39.57.186.42:62755] mod_wsgi (pid=12258): Target WSGI script '/var/www/FlaskApp/flaskapp.wsgi' cannot be loaded as Python module.
[Mon Mar 30 19:59:42.597341 2020] [wsgi:error] [pid 12258] [client 39.57.186.42:62755] mod_wsgi (pid=12258): Exception occurred processing WSGI script '/var/www/FlaskApp/flaskapp.wsgi'.
[Mon Mar 30 19:59:42.598497 2020] [wsgi:error] [pid 12258] [client 39.57.186.42:62755] Traceback (most recent call last):
[Mon Mar 30 19:59:42.598547 2020] [wsgi:error] [pid 12258] [client 39.57.186.42:62755]   File "/var/www/FlaskApp/flaskapp.wsgi", line 7, in <module>
[Mon Mar 30 19:59:42.598561 2020] [wsgi:error] [pid 12258] [client 39.57.186.42:62755]     from FlaskApp import app as application
[Mon Mar 30 19:59:42.598581 2020] [wsgi:error] [pid 12258] [client 39.57.186.42:62755]   File "/var/www/FlaskApp/FlaskApp/__init__.py", line 34, in <module>
[Mon Mar 30 19:59:42.598592 2020] [wsgi:error] [pid 12258] [client 39.57.186.42:62755]     os.makedirs('organizations')
[Mon Mar 30 19:59:42.598619 2020] [wsgi:error] [pid 12258] [client 39.57.186.42:62755]   File "/usr/lib/python3.5/os.py", line 241, in makedirs
[Mon Mar 30 19:59:42.598630 2020] [wsgi:error] [pid 12258] [client 39.57.186.42:62755]     mkdir(name, mode)
[Mon Mar 30 19:59:42.598671 2020] [wsgi:error] [pid 12258] [client 39.57.186.42:62755] PermissionError: [Errno 13] Permission denied: 'organizations'
[Mon Mar 30 20:07:03.544066 2020] [wsgi:error] [pid 12256] [client 39.57.186.42:62879] mod_wsgi (pid=12256): Target WSGI script '/var/www/FlaskApp/flaskapp.wsgi' cannot be loaded as Python module.
[Mon Mar 30 20:07:03.544293 2020] [wsgi:error] [pid 12256] [client 39.57.186.42:62879] mod_wsgi (pid=12256): Exception occurred processing WSGI script '/var/www/FlaskApp/flaskapp.wsgi'.
[Mon Mar 30 20:07:03.546467 2020] [wsgi:error] [pid 12256] [client 39.57.186.42:62879] Traceback (most recent call last):
[Mon Mar 30 20:07:03.546588 2020] [wsgi:error] [pid 12256] [client 39.57.186.42:62879]   File "/var/www/FlaskApp/flaskapp.wsgi", line 7, in <module>
[Mon Mar 30 20:07:03.546615 2020] [wsgi:error] [pid 12256] [client 39.57.186.42:62879]     from FlaskApp import app as application
[Mon Mar 30 20:07:03.546653 2020] [wsgi:error] [pid 12256] [client 39.57.186.42:62879]   File "/var/www/FlaskApp/FlaskApp/__init__.py", line 34, in <module>
[Mon Mar 30 20:07:03.546673 2020] [wsgi:error] [pid 12256] [client 39.57.186.42:62879]     os.makedirs('organizations')
[Mon Mar 30 20:07:03.546722 2020] [wsgi:error] [pid 12256] [client 39.57.186.42:62879]   File "/usr/lib/python3.5/os.py", line 241, in makedirs
[Mon Mar 30 20:07:03.546743 2020] [wsgi:error] [pid 12256] [client 39.57.186.42:62879]     mkdir(name, mode)
[Mon Mar 30 20:07:03.546819 2020] [wsgi:error] [pid 12256] [client 39.57.186.42:62879] PermissionError: [Errno 13] Permission denied: 'organizations'
[Mon Mar 30 20:21:06.245354 2020] [wsgi:error] [pid 12256] [client 39.57.186.42:63006] mod_wsgi (pid=12256): Target WSGI script '/var/www/FlaskApp/flaskapp.wsgi' cannot be loaded as Python module.
[Mon Mar 30 20:21:06.245421 2020] [wsgi:error] [pid 12256] [client 39.57.186.42:63006] mod_wsgi (pid=12256): Exception occurred processing WSGI script '/var/www/FlaskApp/flaskapp.wsgi'.
[Mon Mar 30 20:21:06.245882 2020] [wsgi:error] [pid 12256] [client 39.57.186.42:63006] Traceback (most recent call last):
[Mon Mar 30 20:21:06.245928 2020] [wsgi:error] [pid 12256] [client 39.57.186.42:63006]   File "/var/www/FlaskApp/flaskapp.wsgi", line 7, in <module>
[Mon Mar 30 20:21:06.245940 2020] [wsgi:error] [pid 12256] [client 39.57.186.42:63006]     from FlaskApp import app as application
[Mon Mar 30 20:21:06.245968 2020] [wsgi:error] [pid 12256] [client 39.57.186.42:63006]   File "/var/www/FlaskApp/FlaskApp/__init__.py", line 35, in <module>
[Mon Mar 30 20:21:06.245979 2020] [wsgi:error] [pid 12256] [client 39.57.186.42:63006]     os.makedirs('organizations')
[Mon Mar 30 20:21:06.245995 2020] [wsgi:error] [pid 12256] [client 39.57.186.42:63006]   File "/usr/lib/python3.5/os.py", line 241, in makedirs
[Mon Mar 30 20:21:06.246004 2020] [wsgi:error] [pid 12256] [client 39.57.186.42:63006]     mkdir(name, mode)
[Mon Mar 30 20:21:06.246033 2020] [wsgi:error] [pid 12256] [client 39.57.186.42:63006] PermissionError: [Errno 13] Permission denied: 'organizations'
[Mon Mar 30 20:23:08.479285 2020] [wsgi:error] [pid 12256] [client 39.57.186.42:63019] mod_wsgi (pid=12256): Target WSGI script '/var/www/FlaskApp/flaskapp.wsgi' cannot be loaded as Python module.
[Mon Mar 30 20:23:08.479367 2020] [wsgi:error] [pid 12256] [client 39.57.186.42:63019] mod_wsgi (pid=12256): Exception occurred processing WSGI script '/var/www/FlaskApp/flaskapp.wsgi'.
[Mon Mar 30 20:23:08.479828 2020] [wsgi:error] [pid 12256] [client 39.57.186.42:63019] Traceback (most recent call last):
[Mon Mar 30 20:23:08.479879 2020] [wsgi:error] [pid 12256] [client 39.57.186.42:63019]   File "/var/www/FlaskApp/flaskapp.wsgi", line 7, in <module>
[Mon Mar 30 20:23:08.479893 2020] [wsgi:error] [pid 12256] [client 39.57.186.42:63019]     from FlaskApp import app as application
[Mon Mar 30 20:23:08.479913 2020] [wsgi:error] [pid 12256] [client 39.57.186.42:63019]   File "/var/www/FlaskApp/FlaskApp/__init__.py", line 31, in <module>
[Mon Mar 30 20:23:08.479924 2020] [wsgi:error] [pid 12256] [client 39.57.186.42:63019]     os.makedirs('organizations')
[Mon Mar 30 20:23:08.479943 2020] [wsgi:error] [pid 12256] [client 39.57.186.42:63019]   File "/usr/lib/python3.5/os.py", line 241, in makedirs
[Mon Mar 30 20:23:08.479954 2020] [wsgi:error] [pid 12256] [client 39.57.186.42:63019]     mkdir(name, mode)
[Mon Mar 30 20:23:08.479986 2020] [wsgi:error] [pid 12256] [client 39.57.186.42:63019] PermissionError: [Errno 13] Permission denied: 'organizations'
[Mon Mar 30 20:25:11.728789 2020] [wsgi:error] [pid 12258] [client 39.57.186.42:63027] mod_wsgi (pid=12258): Target WSGI script '/var/www/FlaskApp/flaskapp.wsgi' cannot be loaded as Python module.
[Mon Mar 30 20:25:11.728916 2020] [wsgi:error] [pid 12258] [client 39.57.186.42:63027] mod_wsgi (pid=12258): Exception occurred processing WSGI script '/var/www/FlaskApp/flaskapp.wsgi'.
[Mon Mar 30 20:25:11.729650 2020] [wsgi:error] [pid 12258] [client 39.57.186.42:63027] Traceback (most recent call last):
[Mon Mar 30 20:25:11.729753 2020] [wsgi:error] [pid 12258] [client 39.57.186.42:63027]   File "/var/www/FlaskApp/flaskapp.wsgi", line 7, in <module>
[Mon Mar 30 20:25:11.729784 2020] [wsgi:error] [pid 12258] [client 39.57.186.42:63027]     from FlaskApp import app as application
[Mon Mar 30 20:25:11.729840 2020] [wsgi:error] [pid 12258] [client 39.57.186.42:63027]   File "/var/www/FlaskApp/FlaskApp/__init__.py", line 31, in <module>
[Mon Mar 30 20:25:11.729871 2020] [wsgi:error] [pid 12258] [client 39.57.186.42:63027]     os.makedirs('organizations')
[Mon Mar 30 20:25:11.729925 2020] [wsgi:error] [pid 12258] [client 39.57.186.42:63027]   File "/usr/lib/python3.5/os.py", line 241, in makedirs
[Mon Mar 30 20:25:11.729954 2020] [wsgi:error] [pid 12258] [client 39.57.186.42:63027]     mkdir(name, mode)
[Mon Mar 30 20:25:11.730033 2020] [wsgi:error] [pid 12258] [client 39.57.186.42:63027] PermissionError: [Errno 13] Permission denied: 'organizations'
[Mon Mar 30 20:27:36.722026 2020] [wsgi:error] [pid 12256] [client 39.57.186.42:63031] mod_wsgi (pid=12256): Target WSGI script '/var/www/FlaskApp/flaskapp.wsgi' cannot be loaded as Python module.
[Mon Mar 30 20:27:36.722137 2020] [wsgi:error] [pid 12256] [client 39.57.186.42:63031] mod_wsgi (pid=12256): Exception occurred processing WSGI script '/var/www/FlaskApp/flaskapp.wsgi'.
[Mon Mar 30 20:27:36.722763 2020] [wsgi:error] [pid 12256] [client 39.57.186.42:63031] Traceback (most recent call last):
[Mon Mar 30 20:27:36.722861 2020] [wsgi:error] [pid 12256] [client 39.57.186.42:63031]   File "/var/www/FlaskApp/flaskapp.wsgi", line 7, in <module>
[Mon Mar 30 20:27:36.722893 2020] [wsgi:error] [pid 12256] [client 39.57.186.42:63031]     from FlaskApp import app as application
[Mon Mar 30 20:27:36.722931 2020] [wsgi:error] [pid 12256] [client 39.57.186.42:63031]   File "/var/www/FlaskApp/FlaskApp/__init__.py", line 31, in <module>
[Mon Mar 30 20:27:36.722944 2020] [wsgi:error] [pid 12256] [client 39.57.186.42:63031]     os.makedirs('organizations')
[Mon Mar 30 20:27:36.722964 2020] [wsgi:error] [pid 12256] [client 39.57.186.42:63031]   File "/usr/lib/python3.5/os.py", line 241, in makedirs
[Mon Mar 30 20:27:36.722975 2020] [wsgi:error] [pid 12256] [client 39.57.186.42:63031]     mkdir(name, mode)
[Mon Mar 30 20:27:36.723010 2020] [wsgi:error] [pid 12256] [client 39.57.186.42:63031] PermissionError: [Errno 13] Permission denied: 'organizations'
[Mon Mar 30 20:48:12.654615 2020] [wsgi:error] [pid 12258] [client 39.57.186.42:63204] mod_wsgi (pid=12258): Target WSGI script '/var/www/FlaskApp/flaskapp.wsgi' cannot be loaded as Python module.
[Mon Mar 30 20:48:12.654769 2020] [wsgi:error] [pid 12258] [client 39.57.186.42:63204] mod_wsgi (pid=12258): Exception occurred processing WSGI script '/var/www/FlaskApp/flaskapp.wsgi'.
[Mon Mar 30 20:48:12.655045 2020] [wsgi:error] [pid 12258] [client 39.57.186.42:63204] Traceback (most recent call last):
[Mon Mar 30 20:48:12.655102 2020] [wsgi:error] [pid 12258] [client 39.57.186.42:63204]   File "/var/www/FlaskApp/flaskapp.wsgi", line 7, in <module>
[Mon Mar 30 20:48:12.655124 2020] [wsgi:error] [pid 12258] [client 39.57.186.42:63204]     from FlaskApp import app as application
[Mon Mar 30 20:48:12.655159 2020] [wsgi:error] [pid 12258] [client 39.57.186.42:63204]   File "/var/www/FlaskApp/FlaskApp/__init__.py", line 31, in <module>
[Mon Mar 30 20:48:12.655179 2020] [wsgi:error] [pid 12258] [client 39.57.186.42:63204]     os.makedirs('organizations')
[Mon Mar 30 20:48:12.655214 2020] [wsgi:error] [pid 12258] [client 39.57.186.42:63204]   File "/usr/lib/python3.5/os.py", line 241, in makedirs
[Mon Mar 30 20:48:12.655230 2020] [wsgi:error] [pid 12258] [client 39.57.186.42:63204]     mkdir(name, mode)
[Mon Mar 30 20:48:12.655290 2020] [wsgi:error] [pid 12258] [client 39.57.186.42:63204] PermissionError: [Errno 13] Permission denied: 'organizations'
[Mon Mar 30 20:48:20.591626 2020] [wsgi:error] [pid 14690] [client 39.57.186.42:63203] mod_wsgi (pid=14690): Target WSGI script '/var/www/FlaskApp/flaskapp.wsgi' cannot be loaded as Python module.
[Mon Mar 30 20:48:20.591853 2020] [wsgi:error] [pid 14690] [client 39.57.186.42:63203] mod_wsgi (pid=14690): Exception occurred processing WSGI script '/var/www/FlaskApp/flaskapp.wsgi'.
[Mon Mar 30 20:48:20.594618 2020] [wsgi:error] [pid 14690] [client 39.57.186.42:63203] Traceback (most recent call last):
[Mon Mar 30 20:48:20.594748 2020] [wsgi:error] [pid 14690] [client 39.57.186.42:63203]   File "/var/www/FlaskApp/flaskapp.wsgi", line 7, in <module>
[Mon Mar 30 20:48:20.594778 2020] [wsgi:error] [pid 14690] [client 39.57.186.42:63203]     from FlaskApp import app as application
[Mon Mar 30 20:48:20.594826 2020] [wsgi:error] [pid 14690] [client 39.57.186.42:63203]   File "/var/www/FlaskApp/FlaskApp/__init__.py", line 31, in <module>
[Mon Mar 30 20:48:20.594850 2020] [wsgi:error] [pid 14690] [client 39.57.186.42:63203]     os.makedirs('organizations')
[Mon Mar 30 20:48:20.594898 2020] [wsgi:error] [pid 14690] [client 39.57.186.42:63203]   File "/usr/lib/python3.5/os.py", line 241, in makedirs
[Mon Mar 30 20:48:20.594922 2020] [wsgi:error] [pid 14690] [client 39.57.186.42:63203]     mkdir(name, mode)
[Mon Mar 30 20:48:20.595012 2020] [wsgi:error] [pid 14690] [client 39.57.186.42:63203] PermissionError: [Errno 13] Permission denied: 'organizations'
[Mon Mar 30 20:48:58.228891 2020] [wsgi:error] [pid 14690] [client 39.57.186.42:63214] mod_wsgi (pid=14690): Target WSGI script '/var/www/FlaskApp/flaskapp.wsgi' cannot be loaded as Python module.
[Mon Mar 30 20:48:58.228997 2020] [wsgi:error] [pid 14690] [client 39.57.186.42:63214] mod_wsgi (pid=14690): Exception occurred processing WSGI script '/var/www/FlaskApp/flaskapp.wsgi'.
[Mon Mar 30 20:48:58.229165 2020] [wsgi:error] [pid 14690] [client 39.57.186.42:63214] Traceback (most recent call last):
[Mon Mar 30 20:48:58.229214 2020] [wsgi:error] [pid 14690] [client 39.57.186.42:63214]   File "/var/www/FlaskApp/flaskapp.wsgi", line 7, in <module>
[Mon Mar 30 20:48:58.229228 2020] [wsgi:error] [pid 14690] [client 39.57.186.42:63214]     from FlaskApp import app as application
[Mon Mar 30 20:48:58.229247 2020] [wsgi:error] [pid 14690] [client 39.57.186.42:63214]   File "/var/www/FlaskApp/FlaskApp/__init__.py", line 31, in <module>
[Mon Mar 30 20:48:58.229258 2020] [wsgi:error] [pid 14690] [client 39.57.186.42:63214]     os.makedirs('organizations')
[Mon Mar 30 20:48:58.229276 2020] [wsgi:error] [pid 14690] [client 39.57.186.42:63214]   File "/usr/lib/python3.5/os.py", line 241, in makedirs
[Mon Mar 30 20:48:58.229286 2020] [wsgi:error] [pid 14690] [client 39.57.186.42:63214]     mkdir(name, mode)
[Mon Mar 30 20:48:58.229362 2020] [wsgi:error] [pid 14690] [client 39.57.186.42:63214] PermissionError: [Errno 13] Permission denied: 'organizations'
[Mon Mar 30 20:52:57.792461 2020] [wsgi:error] [pid 12256] [client 39.57.186.42:63258] mod_wsgi (pid=12256): Target WSGI script '/var/www/FlaskApp/flaskapp.wsgi' cannot be loaded as Python module.
[Mon Mar 30 20:52:57.792543 2020] [wsgi:error] [pid 12256] [client 39.57.186.42:63258] mod_wsgi (pid=12256): Exception occurred processing WSGI script '/var/www/FlaskApp/flaskapp.wsgi'.
[Mon Mar 30 20:52:57.792714 2020] [wsgi:error] [pid 12256] [client 39.57.186.42:63258] Traceback (most recent call last):
[Mon Mar 30 20:52:57.792764 2020] [wsgi:error] [pid 12256] [client 39.57.186.42:63258]   File "/var/www/FlaskApp/flaskapp.wsgi", line 7, in <module>
[Mon Mar 30 20:52:57.792777 2020] [wsgi:error] [pid 12256] [client 39.57.186.42:63258]     from FlaskApp import app as application
[Mon Mar 30 20:52:57.792797 2020] [wsgi:error] [pid 12256] [client 39.57.186.42:63258]   File "/var/www/FlaskApp/FlaskApp/__init__.py", line 31, in <module>
[Mon Mar 30 20:52:57.792809 2020] [wsgi:error] [pid 12256] [client 39.57.186.42:63258]     os.makedirs('organizations')
[Mon Mar 30 20:52:57.792827 2020] [wsgi:error] [pid 12256] [client 39.57.186.42:63258]   File "/usr/lib/python3.5/os.py", line 241, in makedirs
[Mon Mar 30 20:52:57.792838 2020] [wsgi:error] [pid 12256] [client 39.57.186.42:63258]     mkdir(name, mode)
[Mon Mar 30 20:52:57.792870 2020] [wsgi:error] [pid 12256] [client 39.57.186.42:63258] PermissionError: [Errno 13] Permission denied: 'organizations'
[Mon Mar 30 20:56:20.852498 2020] [wsgi:error] [pid 14690] [client 39.57.186.42:63297] mod_wsgi (pid=14690): Target WSGI script '/var/www/FlaskApp/flaskapp.wsgi' cannot be loaded as Python module.
[Mon Mar 30 20:56:20.852689 2020] [wsgi:error] [pid 14690] [client 39.57.186.42:63297] mod_wsgi (pid=14690): Exception occurred processing WSGI script '/var/www/FlaskApp/flaskapp.wsgi'.
[Mon Mar 30 20:56:20.852954 2020] [wsgi:error] [pid 14690] [client 39.57.186.42:63297] Traceback (most recent call last):
[Mon Mar 30 20:56:20.853030 2020] [wsgi:error] [pid 14690] [client 39.57.186.42:63297]   File "/var/www/FlaskApp/flaskapp.wsgi", line 7, in <module>
[Mon Mar 30 20:56:20.853049 2020] [wsgi:error] [pid 14690] [client 39.57.186.42:63297]     from FlaskApp import app as application
[Mon Mar 30 20:56:20.853078 2020] [wsgi:error] [pid 14690] [client 39.57.186.42:63297]   File "/var/www/FlaskApp/FlaskApp/__init__.py", line 31, in <module>
[Mon Mar 30 20:56:20.853095 2020] [wsgi:error] [pid 14690] [client 39.57.186.42:63297]     os.makedirs('organizations')
[Mon Mar 30 20:56:20.853122 2020] [wsgi:error] [pid 14690] [client 39.57.186.42:63297]   File "/usr/lib/python3.5/os.py", line 241, in makedirs
[Mon Mar 30 20:56:20.853137 2020] [wsgi:error] [pid 14690] [client 39.57.186.42:63297]     mkdir(name, mode)
[Mon Mar 30 20:56:20.853209 2020] [wsgi:error] [pid 14690] [client 39.57.186.42:63297] PermissionError: [Errno 13] Permission denied: 'organizations'
[Mon Mar 30 20:58:08.864780 2020] [wsgi:error] [pid 12256] [client 39.57.186.42:63306] mod_wsgi (pid=12256): Target WSGI script '/var/www/FlaskApp/flaskapp.wsgi' cannot be loaded as Python module.
[Mon Mar 30 20:58:08.864922 2020] [wsgi:error] [pid 12256] [client 39.57.186.42:63306] mod_wsgi (pid=12256): Exception occurred processing WSGI script '/var/www/FlaskApp/flaskapp.wsgi'.
[Mon Mar 30 20:58:08.865112 2020] [wsgi:error] [pid 12256] [client 39.57.186.42:63306] Traceback (most recent call last):
[Mon Mar 30 20:58:08.865163 2020] [wsgi:error] [pid 12256] [client 39.57.186.42:63306]   File "/var/www/FlaskApp/flaskapp.wsgi", line 7, in <module>
[Mon Mar 30 20:58:08.865177 2020] [wsgi:error] [pid 12256] [client 39.57.186.42:63306]     from FlaskApp import app as application
[Mon Mar 30 20:58:08.865198 2020] [wsgi:error] [pid 12256] [client 39.57.186.42:63306]   File "/var/www/FlaskApp/FlaskApp/__init__.py", line 31, in <module>
[Mon Mar 30 20:58:08.865209 2020] [wsgi:error] [pid 12256] [client 39.57.186.42:63306]     os.makedirs('organizations')
[Mon Mar 30 20:58:08.865227 2020] [wsgi:error] [pid 12256] [client 39.57.186.42:63306]   File "/usr/lib/python3.5/os.py", line 241, in makedirs
[Mon Mar 30 20:58:08.865238 2020] [wsgi:error] [pid 12256] [client 39.57.186.42:63306]     mkdir(name, mode)
[Mon Mar 30 20:58:08.865271 2020] [wsgi:error] [pid 12256] [client 39.57.186.42:63306] PermissionError: [Errno 13] Permission denied: 'organizations'
[Mon Mar 30 21:01:04.790118 2020] [wsgi:error] [pid 12256] [client 39.57.186.42:63327] mod_wsgi (pid=12256): Target WSGI script '/var/www/FlaskApp/flaskapp.wsgi' cannot be loaded as Python module.
[Mon Mar 30 21:01:04.790280 2020] [wsgi:error] [pid 12256] [client 39.57.186.42:63327] mod_wsgi (pid=12256): Exception occurred processing WSGI script '/var/www/FlaskApp/flaskapp.wsgi'.
[Mon Mar 30 21:01:04.791001 2020] [wsgi:error] [pid 12256] [client 39.57.186.42:63327] Traceback (most recent call last):
[Mon Mar 30 21:01:04.791069 2020] [wsgi:error] [pid 12256] [client 39.57.186.42:63327]   File "/var/www/FlaskApp/flaskapp.wsgi", line 7, in <module>
[Mon Mar 30 21:01:04.791085 2020] [wsgi:error] [pid 12256] [client 39.57.186.42:63327]     from FlaskApp import app as application
[Mon Mar 30 21:01:04.791111 2020] [wsgi:error] [pid 12256] [client 39.57.186.42:63327]   File "/var/www/FlaskApp/FlaskApp/__init__.py", line 31, in <module>
[Mon Mar 30 21:01:04.791126 2020] [wsgi:error] [pid 12256] [client 39.57.186.42:63327]     os.makedirs('organizations')
[Mon Mar 30 21:01:04.791196 2020] [wsgi:error] [pid 12256] [client 39.57.186.42:63327]   File "/usr/lib/python3.5/os.py", line 241, in makedirs
[Mon Mar 30 21:01:04.791214 2020] [wsgi:error] [pid 12256] [client 39.57.186.42:63327]     mkdir(name, mode)
[Mon Mar 30 21:01:04.791260 2020] [wsgi:error] [pid 12256] [client 39.57.186.42:63327] PermissionError: [Errno 13] Permission denied: 'organizations'
[Mon Mar 30 21:01:15.757367 2020] [wsgi:error] [pid 12258] [client 39.57.186.42:63330] mod_wsgi (pid=12258): Target WSGI script '/var/www/FlaskApp/flaskapp.wsgi' cannot be loaded as Python module.
[Mon Mar 30 21:01:15.757449 2020] [wsgi:error] [pid 12258] [client 39.57.186.42:63330] mod_wsgi (pid=12258): Exception occurred processing WSGI script '/var/www/FlaskApp/flaskapp.wsgi'.
[Mon Mar 30 21:01:15.757988 2020] [wsgi:error] [pid 12258] [client 39.57.186.42:63330] Traceback (most recent call last):
[Mon Mar 30 21:01:15.758040 2020] [wsgi:error] [pid 12258] [client 39.57.186.42:63330]   File "/var/www/FlaskApp/flaskapp.wsgi", line 7, in <module>
[Mon Mar 30 21:01:15.758053 2020] [wsgi:error] [pid 12258] [client 39.57.186.42:63330]     from FlaskApp import app as application
[Mon Mar 30 21:01:15.758073 2020] [wsgi:error] [pid 12258] [client 39.57.186.42:63330]   File "/var/www/FlaskApp/FlaskApp/__init__.py", line 31, in <module>
[Mon Mar 30 21:01:15.758098 2020] [wsgi:error] [pid 12258] [client 39.57.186.42:63330]     os.makedirs('organizations')
[Mon Mar 30 21:01:15.758118 2020] [wsgi:error] [pid 12258] [client 39.57.186.42:63330]   File "/usr/lib/python3.5/os.py", line 241, in makedirs
[Mon Mar 30 21:01:15.758129 2020] [wsgi:error] [pid 12258] [client 39.57.186.42:63330]     mkdir(name, mode)
[Mon Mar 30 21:01:15.758161 2020] [wsgi:error] [pid 12258] [client 39.57.186.42:63330] PermissionError: [Errno 13] Permission denied: 'organizations'
[Tue Mar 31 04:14:35.866382 2020] [wsgi:error] [pid 12258] [client 171.67.70.85:50588] mod_wsgi (pid=12258): Target WSGI script '/var/www/FlaskApp/flaskapp.wsgi' cannot be loaded as Python module.
[Tue Mar 31 04:14:35.866502 2020] [wsgi:error] [pid 12258] [client 171.67.70.85:50588] mod_wsgi (pid=12258): Exception occurred processing WSGI script '/var/www/FlaskApp/flaskapp.wsgi'.
[Tue Mar 31 04:14:35.866816 2020] [wsgi:error] [pid 12258] [client 171.67.70.85:50588] Traceback (most recent call last):
[Tue Mar 31 04:14:35.866900 2020] [wsgi:error] [pid 12258] [client 171.67.70.85:50588]   File "/var/www/FlaskApp/flaskapp.wsgi", line 7, in <module>
[Tue Mar 31 04:14:35.866924 2020] [wsgi:error] [pid 12258] [client 171.67.70.85:50588]     from FlaskApp import app as application
[Tue Mar 31 04:14:35.866965 2020] [wsgi:error] [pid 12258] [client 171.67.70.85:50588]   File "/var/www/FlaskApp/FlaskApp/__init__.py", line 31, in <module>
[Tue Mar 31 04:14:35.866987 2020] [wsgi:error] [pid 12258] [client 171.67.70.85:50588]     os.makedirs('organizations')
[Tue Mar 31 04:14:35.867025 2020] [wsgi:error] [pid 12258] [client 171.67.70.85:50588]   File "/usr/lib/python3.5/os.py", line 241, in makedirs
[Tue Mar 31 04:14:35.867046 2020] [wsgi:error] [pid 12258] [client 171.67.70.85:50588]     mkdir(name, mode)
[Tue Mar 31 04:14:35.867108 2020] [wsgi:error] [pid 12258] [client 171.67.70.85:50588] PermissionError: [Errno 13] Permission denied: 'organizations'
[Tue Mar 31 04:16:04.811530 2020] [wsgi:error] [pid 14690] [client 95.140.24.78:60479] mod_wsgi (pid=14690): Target WSGI script '/var/www/FlaskApp/flaskapp.wsgi' cannot be loaded as Python module.
[Tue Mar 31 04:16:04.811613 2020] [wsgi:error] [pid 14690] [client 95.140.24.78:60479] mod_wsgi (pid=14690): Exception occurred processing WSGI script '/var/www/FlaskApp/flaskapp.wsgi'.
[Tue Mar 31 04:16:04.812013 2020] [wsgi:error] [pid 14690] [client 95.140.24.78:60479] Traceback (most recent call last):
[Tue Mar 31 04:16:04.812068 2020] [wsgi:error] [pid 14690] [client 95.140.24.78:60479]   File "/var/www/FlaskApp/flaskapp.wsgi", line 7, in <module>
[Tue Mar 31 04:16:04.812080 2020] [wsgi:error] [pid 14690] [client 95.140.24.78:60479]     from FlaskApp import app as application
[Tue Mar 31 04:16:04.812096 2020] [wsgi:error] [pid 14690] [client 95.140.24.78:60479]   File "/var/www/FlaskApp/FlaskApp/__init__.py", line 31, in <module>
[Tue Mar 31 04:16:04.812106 2020] [wsgi:error] [pid 14690] [client 95.140.24.78:60479]     os.makedirs('organizations')
[Tue Mar 31 04:16:04.812121 2020] [wsgi:error] [pid 14690] [client 95.140.24.78:60479]   File "/usr/lib/python3.5/os.py", line 241, in makedirs
[Tue Mar 31 04:16:04.812131 2020] [wsgi:error] [pid 14690] [client 95.140.24.78:60479]     mkdir(name, mode)
[Tue Mar 31 04:16:04.812158 2020] [wsgi:error] [pid 14690] [client 95.140.24.78:60479] PermissionError: [Errno 13] Permission denied: 'organizations'
[Tue Mar 31 05:25:15.833023 2020] [wsgi:error] [pid 12256] [client 39.57.186.42:63876] mod_wsgi (pid=12256): Target WSGI script '/var/www/FlaskApp/flaskapp.wsgi' cannot be loaded as Python module.
[Tue Mar 31 05:25:15.833120 2020] [wsgi:error] [pid 12256] [client 39.57.186.42:63876] mod_wsgi (pid=12256): Exception occurred processing WSGI script '/var/www/FlaskApp/flaskapp.wsgi'.
[Tue Mar 31 05:25:15.833291 2020] [wsgi:error] [pid 12256] [client 39.57.186.42:63876] Traceback (most recent call last):
[Tue Mar 31 05:25:15.833401 2020] [wsgi:error] [pid 12256] [client 39.57.186.42:63876]   File "/var/www/FlaskApp/flaskapp.wsgi", line 7, in <module>
[Tue Mar 31 05:25:15.833439 2020] [wsgi:error] [pid 12256] [client 39.57.186.42:63876]     from FlaskApp import app as application
[Tue Mar 31 05:25:15.833461 2020] [wsgi:error] [pid 12256] [client 39.57.186.42:63876]   File "/var/www/FlaskApp/FlaskApp/__init__.py", line 31, in <module>
[Tue Mar 31 05:25:15.833472 2020] [wsgi:error] [pid 12256] [client 39.57.186.42:63876]     os.makedirs('organizations')
[Tue Mar 31 05:25:15.833491 2020] [wsgi:error] [pid 12256] [client 39.57.186.42:63876]   File "/usr/lib/python3.5/os.py", line 241, in makedirs
[Tue Mar 31 05:25:15.833501 2020] [wsgi:error] [pid 12256] [client 39.57.186.42:63876]     mkdir(name, mode)
[Tue Mar 31 05:25:15.833534 2020] [wsgi:error] [pid 12256] [client 39.57.186.42:63876] PermissionError: [Errno 13] Permission denied: 'organizations'
[Tue Mar 31 05:26:19.308743 2020] [wsgi:error] [pid 12258] [client 39.57.186.42:63895] mod_wsgi (pid=12258): Target WSGI script '/var/www/FlaskApp/flaskapp.wsgi' cannot be loaded as Python module.
[Tue Mar 31 05:26:19.308955 2020] [wsgi:error] [pid 12258] [client 39.57.186.42:63895] mod_wsgi (pid=12258): Exception occurred processing WSGI script '/var/www/FlaskApp/flaskapp.wsgi'.
[Tue Mar 31 05:26:19.309505 2020] [wsgi:error] [pid 12258] [client 39.57.186.42:63895] Traceback (most recent call last):
[Tue Mar 31 05:26:19.309557 2020] [wsgi:error] [pid 12258] [client 39.57.186.42:63895]   File "/var/www/FlaskApp/flaskapp.wsgi", line 7, in <module>
[Tue Mar 31 05:26:19.309570 2020] [wsgi:error] [pid 12258] [client 39.57.186.42:63895]     from FlaskApp import app as application
[Tue Mar 31 05:26:19.309590 2020] [wsgi:error] [pid 12258] [client 39.57.186.42:63895]   File "/var/www/FlaskApp/FlaskApp/__init__.py", line 31, in <module>
[Tue Mar 31 05:26:19.309601 2020] [wsgi:error] [pid 12258] [client 39.57.186.42:63895]     os.makedirs('organizations')
[Tue Mar 31 05:26:19.309619 2020] [wsgi:error] [pid 12258] [client 39.57.186.42:63895]   File "/usr/lib/python3.5/os.py", line 241, in makedirs
[Tue Mar 31 05:26:19.309631 2020] [wsgi:error] [pid 12258] [client 39.57.186.42:63895]     mkdir(name, mode)
[Tue Mar 31 05:26:19.309663 2020] [wsgi:error] [pid 12258] [client 39.57.186.42:63895] PermissionError: [Errno 13] Permission denied: 'organizations'
[Tue Mar 31 05:26:22.532577 2020] [wsgi:error] [pid 14690] [client 39.57.186.42:63894] mod_wsgi (pid=14690): Target WSGI script '/var/www/FlaskApp/flaskapp.wsgi' cannot be loaded as Python module.
[Tue Mar 31 05:26:22.532677 2020] [wsgi:error] [pid 14690] [client 39.57.186.42:63894] mod_wsgi (pid=14690): Exception occurred processing WSGI script '/var/www/FlaskApp/flaskapp.wsgi'.
[Tue Mar 31 05:26:22.533414 2020] [wsgi:error] [pid 14690] [client 39.57.186.42:63894] Traceback (most recent call last):
[Tue Mar 31 05:26:22.533490 2020] [wsgi:error] [pid 14690] [client 39.57.186.42:63894]   File "/var/www/FlaskApp/flaskapp.wsgi", line 7, in <module>
[Tue Mar 31 05:26:22.533509 2020] [wsgi:error] [pid 14690] [client 39.57.186.42:63894]     from FlaskApp import app as application
[Tue Mar 31 05:26:22.533540 2020] [wsgi:error] [pid 14690] [client 39.57.186.42:63894]   File "/var/www/FlaskApp/FlaskApp/__init__.py", line 31, in <module>
[Tue Mar 31 05:26:22.533558 2020] [wsgi:error] [pid 14690] [client 39.57.186.42:63894]     os.makedirs('organizations')
[Tue Mar 31 05:26:22.533587 2020] [wsgi:error] [pid 14690] [client 39.57.186.42:63894]   File "/usr/lib/python3.5/os.py", line 241, in makedirs
[Tue Mar 31 05:26:22.533604 2020] [wsgi:error] [pid 14690] [client 39.57.186.42:63894]     mkdir(name, mode)
[Tue Mar 31 05:26:22.533650 2020] [wsgi:error] [pid 14690] [client 39.57.186.42:63894] PermissionError: [Errno 13] Permission denied: 'organizations'
[Tue Mar 31 05:39:19.518676 2020] [wsgi:error] [pid 14690] [client 39.57.186.42:63979] mod_wsgi (pid=14690): Target WSGI script '/var/www/FlaskApp/flaskapp.wsgi' cannot be loaded as Python module.
[Tue Mar 31 05:39:19.518776 2020] [wsgi:error] [pid 14690] [client 39.57.186.42:63979] mod_wsgi (pid=14690): Exception occurred processing WSGI script '/var/www/FlaskApp/flaskapp.wsgi'.
[Tue Mar 31 05:39:19.518965 2020] [wsgi:error] [pid 14690] [client 39.57.186.42:63979] Traceback (most recent call last):
[Tue Mar 31 05:39:19.519015 2020] [wsgi:error] [pid 14690] [client 39.57.186.42:63979]   File "/var/www/FlaskApp/flaskapp.wsgi", line 7, in <module>
[Tue Mar 31 05:39:19.519028 2020] [wsgi:error] [pid 14690] [client 39.57.186.42:63979]     from FlaskApp import app as application
[Tue Mar 31 05:39:19.519048 2020] [wsgi:error] [pid 14690] [client 39.57.186.42:63979]   File "/var/www/FlaskApp/FlaskApp/__init__.py", line 31, in <module>
[Tue Mar 31 05:39:19.519058 2020] [wsgi:error] [pid 14690] [client 39.57.186.42:63979]     os.makedirs('organizations')
[Tue Mar 31 05:39:19.519076 2020] [wsgi:error] [pid 14690] [client 39.57.186.42:63979]   File "/usr/lib/python3.5/os.py", line 241, in makedirs
[Tue Mar 31 05:39:19.519086 2020] [wsgi:error] [pid 14690] [client 39.57.186.42:63979]     mkdir(name, mode)
[Tue Mar 31 05:39:19.519117 2020] [wsgi:error] [pid 14690] [client 39.57.186.42:63979] PermissionError: [Errno 13] Permission denied: 'organizations'
[Tue Mar 31 05:42:12.960616 2020] [mpm_prefork:notice] [pid 12251] AH00169: caught SIGTERM, shutting down
[Tue Mar 31 05:42:14.021551 2020] [mpm_prefork:notice] [pid 55436] AH00163: Apache/2.4.18 (Ubuntu) mod_wsgi/4.3.0 Python/3.5.2 configured -- resuming normal operations
[Tue Mar 31 05:42:14.021730 2020] [core:notice] [pid 55436] AH00094: Command line: '/usr/sbin/apache2'
[Tue Mar 31 05:42:20.660987 2020] [wsgi:error] [pid 55439] [client 39.57.186.42:64030] mod_wsgi (pid=55439): Target WSGI script '/var/www/FlaskApp/flaskapp.wsgi' cannot be loaded as Python module.
[Tue Mar 31 05:42:20.661286 2020] [wsgi:error] [pid 55439] [client 39.57.186.42:64030] mod_wsgi (pid=55439): Exception occurred processing WSGI script '/var/www/FlaskApp/flaskapp.wsgi'.
[Tue Mar 31 05:42:20.662985 2020] [wsgi:error] [pid 55439] [client 39.57.186.42:64030] Traceback (most recent call last):
[Tue Mar 31 05:42:20.663083 2020] [wsgi:error] [pid 55439] [client 39.57.186.42:64030]   File "/var/www/FlaskApp/flaskapp.wsgi", line 7, in <module>
[Tue Mar 31 05:42:20.663098 2020] [wsgi:error] [pid 55439] [client 39.57.186.42:64030]     from FlaskApp import app as application
[Tue Mar 31 05:42:20.663118 2020] [wsgi:error] [pid 55439] [client 39.57.186.42:64030]   File "/var/www/FlaskApp/FlaskApp/__init__.py", line 31, in <module>
[Tue Mar 31 05:42:20.663129 2020] [wsgi:error] [pid 55439] [client 39.57.186.42:64030]     os.makedirs('organizations')
[Tue Mar 31 05:42:20.663148 2020] [wsgi:error] [pid 55439] [client 39.57.186.42:64030]   File "/usr/lib/python3.5/os.py", line 241, in makedirs
[Tue Mar 31 05:42:20.663194 2020] [wsgi:error] [pid 55439] [client 39.57.186.42:64030]     mkdir(name, mode)
[Tue Mar 31 05:42:20.663254 2020] [wsgi:error] [pid 55439] [client 39.57.186.42:64030] PermissionError: [Errno 13] Permission denied: 'organizations'
[Tue Mar 31 05:44:44.925229 2020] [wsgi:error] [pid 55441] [client 95.111.141.205:49930] mod_wsgi (pid=55441): Target WSGI script '/var/www/FlaskApp/flaskapp.wsgi' cannot be loaded as Python module.
[Tue Mar 31 05:44:44.925443 2020] [wsgi:error] [pid 55441] [client 95.111.141.205:49930] mod_wsgi (pid=55441): Exception occurred processing WSGI script '/var/www/FlaskApp/flaskapp.wsgi'.
[Tue Mar 31 05:44:44.926945 2020] [wsgi:error] [pid 55441] [client 95.111.141.205:49930] Traceback (most recent call last):
[Tue Mar 31 05:44:44.927008 2020] [wsgi:error] [pid 55441] [client 95.111.141.205:49930]   File "/var/www/FlaskApp/flaskapp.wsgi", line 7, in <module>
[Tue Mar 31 05:44:44.927022 2020] [wsgi:error] [pid 55441] [client 95.111.141.205:49930]     from FlaskApp import app as application
[Tue Mar 31 05:44:44.927042 2020] [wsgi:error] [pid 55441] [client 95.111.141.205:49930]   File "/var/www/FlaskApp/FlaskApp/__init__.py", line 31, in <module>
[Tue Mar 31 05:44:44.927053 2020] [wsgi:error] [pid 55441] [client 95.111.141.205:49930]     os.makedirs('organizations')
[Tue Mar 31 05:44:44.927071 2020] [wsgi:error] [pid 55441] [client 95.111.141.205:49930]   File "/usr/lib/python3.5/os.py", line 241, in makedirs
[Tue Mar 31 05:44:44.927098 2020] [wsgi:error] [pid 55441] [client 95.111.141.205:49930]     mkdir(name, mode)
[Tue Mar 31 05:44:44.927142 2020] [wsgi:error] [pid 55441] [client 95.111.141.205:49930] PermissionError: [Errno 13] Permission denied: 'organizations'
[Tue Mar 31 06:51:02.987621 2020] [wsgi:error] [pid 55443] [client 109.111.159.220:37736] mod_wsgi (pid=55443): Target WSGI script '/var/www/FlaskApp/flaskapp.wsgi' cannot be loaded as Python module.
[Tue Mar 31 06:51:02.987854 2020] [wsgi:error] [pid 55443] [client 109.111.159.220:37736] mod_wsgi (pid=55443): Exception occurred processing WSGI script '/var/www/FlaskApp/flaskapp.wsgi'.
[Tue Mar 31 06:51:02.990111 2020] [wsgi:error] [pid 55443] [client 109.111.159.220:37736] Traceback (most recent call last):
[Tue Mar 31 06:51:02.990245 2020] [wsgi:error] [pid 55443] [client 109.111.159.220:37736]   File "/var/www/FlaskApp/flaskapp.wsgi", line 7, in <module>
[Tue Mar 31 06:51:02.990268 2020] [wsgi:error] [pid 55443] [client 109.111.159.220:37736]     from FlaskApp import app as application
[Tue Mar 31 06:51:02.990308 2020] [wsgi:error] [pid 55443] [client 109.111.159.220:37736]   File "/var/www/FlaskApp/FlaskApp/__init__.py", line 31, in <module>
[Tue Mar 31 06:51:02.990330 2020] [wsgi:error] [pid 55443] [client 109.111.159.220:37736]     os.makedirs('organizations')
[Tue Mar 31 06:51:02.990368 2020] [wsgi:error] [pid 55443] [client 109.111.159.220:37736]   File "/usr/lib/python3.5/os.py", line 241, in makedirs
[Tue Mar 31 06:51:02.990390 2020] [wsgi:error] [pid 55443] [client 109.111.159.220:37736]     mkdir(name, mode)
[Tue Mar 31 06:51:02.990467 2020] [wsgi:error] [pid 55443] [client 109.111.159.220:37736] PermissionError: [Errno 13] Permission denied: 'organizations'
[Tue Mar 31 07:30:04.313428 2020] [wsgi:error] [pid 55447] [client 198.108.66.144:52970] mod_wsgi (pid=55447): Target WSGI script '/var/www/FlaskApp/flaskapp.wsgi' cannot be loaded as Python module.
[Tue Mar 31 07:30:04.313634 2020] [wsgi:error] [pid 55447] [client 198.108.66.144:52970] mod_wsgi (pid=55447): Exception occurred processing WSGI script '/var/www/FlaskApp/flaskapp.wsgi'.
[Tue Mar 31 07:30:04.315170 2020] [wsgi:error] [pid 55447] [client 198.108.66.144:52970] Traceback (most recent call last):
[Tue Mar 31 07:30:04.315235 2020] [wsgi:error] [pid 55447] [client 198.108.66.144:52970]   File "/var/www/FlaskApp/flaskapp.wsgi", line 7, in <module>
[Tue Mar 31 07:30:04.315249 2020] [wsgi:error] [pid 55447] [client 198.108.66.144:52970]     from FlaskApp import app as application
[Tue Mar 31 07:30:04.315269 2020] [wsgi:error] [pid 55447] [client 198.108.66.144:52970]   File "/var/www/FlaskApp/FlaskApp/__init__.py", line 31, in <module>
[Tue Mar 31 07:30:04.315280 2020] [wsgi:error] [pid 55447] [client 198.108.66.144:52970]     os.makedirs('organizations')
[Tue Mar 31 07:30:04.315298 2020] [wsgi:error] [pid 55447] [client 198.108.66.144:52970]   File "/usr/lib/python3.5/os.py", line 241, in makedirs
[Tue Mar 31 07:30:04.315320 2020] [wsgi:error] [pid 55447] [client 198.108.66.144:52970]     mkdir(name, mode)
[Tue Mar 31 07:30:04.315394 2020] [wsgi:error] [pid 55447] [client 198.108.66.144:52970] PermissionError: [Errno 13] Permission denied: 'organizations'
[Tue Mar 31 08:10:25.408613 2020] [wsgi:error] [pid 55439] [client 39.57.186.42:64472] mod_wsgi (pid=55439): Target WSGI script '/var/www/FlaskApp/flaskapp.wsgi' cannot be loaded as Python module.
[Tue Mar 31 08:10:25.408691 2020] [wsgi:error] [pid 55439] [client 39.57.186.42:64472] mod_wsgi (pid=55439): Exception occurred processing WSGI script '/var/www/FlaskApp/flaskapp.wsgi'.
[Tue Mar 31 08:10:25.408858 2020] [wsgi:error] [pid 55439] [client 39.57.186.42:64472] Traceback (most recent call last):
[Tue Mar 31 08:10:25.408908 2020] [wsgi:error] [pid 55439] [client 39.57.186.42:64472]   File "/var/www/FlaskApp/flaskapp.wsgi", line 7, in <module>
[Tue Mar 31 08:10:25.408921 2020] [wsgi:error] [pid 55439] [client 39.57.186.42:64472]     from FlaskApp import app as application
[Tue Mar 31 08:10:25.408958 2020] [wsgi:error] [pid 55439] [client 39.57.186.42:64472]   File "/var/www/FlaskApp/FlaskApp/__init__.py", line 31, in <module>
[Tue Mar 31 08:10:25.408970 2020] [wsgi:error] [pid 55439] [client 39.57.186.42:64472]     os.makedirs('organizations')
[Tue Mar 31 08:10:25.408988 2020] [wsgi:error] [pid 55439] [client 39.57.186.42:64472]   File "/usr/lib/python3.5/os.py", line 241, in makedirs
[Tue Mar 31 08:10:25.408998 2020] [wsgi:error] [pid 55439] [client 39.57.186.42:64472]     mkdir(name, mode)
[Tue Mar 31 08:10:25.409030 2020] [wsgi:error] [pid 55439] [client 39.57.186.42:64472] PermissionError: [Errno 13] Permission denied: 'organizations'
[Tue Mar 31 08:10:29.285990 2020] [wsgi:error] [pid 55450] [client 39.57.186.42:64471] mod_wsgi (pid=55450): Target WSGI script '/var/www/FlaskApp/flaskapp.wsgi' cannot be loaded as Python module.
[Tue Mar 31 08:10:29.286118 2020] [wsgi:error] [pid 55450] [client 39.57.186.42:64471] mod_wsgi (pid=55450): Exception occurred processing WSGI script '/var/www/FlaskApp/flaskapp.wsgi'.
[Tue Mar 31 08:10:29.287301 2020] [wsgi:error] [pid 55450] [client 39.57.186.42:64471] Traceback (most recent call last):
[Tue Mar 31 08:10:29.287360 2020] [wsgi:error] [pid 55450] [client 39.57.186.42:64471]   File "/var/www/FlaskApp/flaskapp.wsgi", line 7, in <module>
[Tue Mar 31 08:10:29.287373 2020] [wsgi:error] [pid 55450] [client 39.57.186.42:64471]     from FlaskApp import app as application
[Tue Mar 31 08:10:29.287392 2020] [wsgi:error] [pid 55450] [client 39.57.186.42:64471]   File "/var/www/FlaskApp/FlaskApp/__init__.py", line 31, in <module>
[Tue Mar 31 08:10:29.287403 2020] [wsgi:error] [pid 55450] [client 39.57.186.42:64471]     os.makedirs('organizations')
[Tue Mar 31 08:10:29.287420 2020] [wsgi:error] [pid 55450] [client 39.57.186.42:64471]   File "/usr/lib/python3.5/os.py", line 241, in makedirs
[Tue Mar 31 08:10:29.287430 2020] [wsgi:error] [pid 55450] [client 39.57.186.42:64471]     mkdir(name, mode)
[Tue Mar 31 08:10:29.287471 2020] [wsgi:error] [pid 55450] [client 39.57.186.42:64471] PermissionError: [Errno 13] Permission denied: 'organizations'
[Tue Mar 31 08:10:35.897348 2020] [wsgi:error] [pid 55440] [client 39.57.186.42:64473] mod_wsgi (pid=55440): Target WSGI script '/var/www/FlaskApp/flaskapp.wsgi' cannot be loaded as Python module.
[Tue Mar 31 08:10:35.897489 2020] [wsgi:error] [pid 55440] [client 39.57.186.42:64473] mod_wsgi (pid=55440): Exception occurred processing WSGI script '/var/www/FlaskApp/flaskapp.wsgi'.
[Tue Mar 31 08:10:35.898684 2020] [wsgi:error] [pid 55440] [client 39.57.186.42:64473] Traceback (most recent call last):
[Tue Mar 31 08:10:35.898748 2020] [wsgi:error] [pid 55440] [client 39.57.186.42:64473]   File "/var/www/FlaskApp/flaskapp.wsgi", line 7, in <module>
[Tue Mar 31 08:10:35.898769 2020] [wsgi:error] [pid 55440] [client 39.57.186.42:64473]     from FlaskApp import app as application
[Tue Mar 31 08:10:35.898792 2020] [wsgi:error] [pid 55440] [client 39.57.186.42:64473]   File "/var/www/FlaskApp/FlaskApp/__init__.py", line 31, in <module>
[Tue Mar 31 08:10:35.898803 2020] [wsgi:error] [pid 55440] [client 39.57.186.42:64473]     os.makedirs('organizations')
[Tue Mar 31 08:10:35.898822 2020] [wsgi:error] [pid 55440] [client 39.57.186.42:64473]   File "/usr/lib/python3.5/os.py", line 241, in makedirs
[Tue Mar 31 08:10:35.898833 2020] [wsgi:error] [pid 55440] [client 39.57.186.42:64473]     mkdir(name, mode)
[Tue Mar 31 08:10:35.898874 2020] [wsgi:error] [pid 55440] [client 39.57.186.42:64473] PermissionError: [Errno 13] Permission denied: 'organizations'
[Tue Mar 31 08:12:11.608486 2020] [mpm_prefork:notice] [pid 55436] AH00169: caught SIGTERM, shutting down
[Tue Mar 31 08:12:12.646365 2020] [mpm_prefork:notice] [pid 2322] AH00163: Apache/2.4.18 (Ubuntu) mod_wsgi/4.3.0 Python/3.5.2 configured -- resuming normal operations
[Tue Mar 31 08:12:12.646496 2020] [core:notice] [pid 2322] AH00094: Command line: '/usr/sbin/apache2'
[Tue Mar 31 08:12:24.185792 2020] [wsgi:error] [pid 2325] [client 39.57.186.42:58606] mod_wsgi (pid=2325): Target WSGI script '/var/www/FlaskApp/flaskapp.wsgi' cannot be loaded as Python module.
[Tue Mar 31 08:12:24.185969 2020] [wsgi:error] [pid 2325] [client 39.57.186.42:58606] mod_wsgi (pid=2325): Exception occurred processing WSGI script '/var/www/FlaskApp/flaskapp.wsgi'.
[Tue Mar 31 08:12:24.187402 2020] [wsgi:error] [pid 2325] [client 39.57.186.42:58606] Traceback (most recent call last):
[Tue Mar 31 08:12:24.187471 2020] [wsgi:error] [pid 2325] [client 39.57.186.42:58606]   File "/var/www/FlaskApp/flaskapp.wsgi", line 7, in <module>
[Tue Mar 31 08:12:24.187486 2020] [wsgi:error] [pid 2325] [client 39.57.186.42:58606]     from FlaskApp import app as application
[Tue Mar 31 08:12:24.187509 2020] [wsgi:error] [pid 2325] [client 39.57.186.42:58606]   File "/var/www/FlaskApp/FlaskApp/__init__.py", line 31, in <module>
[Tue Mar 31 08:12:24.187521 2020] [wsgi:error] [pid 2325] [client 39.57.186.42:58606]     os.makedirs('organizations')
[Tue Mar 31 08:12:24.187543 2020] [wsgi:error] [pid 2325] [client 39.57.186.42:58606]   File "/usr/lib/python3.5/os.py", line 241, in makedirs
[Tue Mar 31 08:12:24.187555 2020] [wsgi:error] [pid 2325] [client 39.57.186.42:58606]     mkdir(name, mode)
[Tue Mar 31 08:12:24.187602 2020] [wsgi:error] [pid 2325] [client 39.57.186.42:58606] PermissionError: [Errno 13] Permission denied: 'organizations'
[Tue Mar 31 08:12:29.385346 2020] [wsgi:error] [pid 2326] [client 39.57.186.42:58605] mod_wsgi (pid=2326): Target WSGI script '/var/www/FlaskApp/flaskapp.wsgi' cannot be loaded as Python module.
[Tue Mar 31 08:12:29.385529 2020] [wsgi:error] [pid 2326] [client 39.57.186.42:58605] mod_wsgi (pid=2326): Exception occurred processing WSGI script '/var/www/FlaskApp/flaskapp.wsgi'.
[Tue Mar 31 08:12:29.386868 2020] [wsgi:error] [pid 2326] [client 39.57.186.42:58605] Traceback (most recent call last):
[Tue Mar 31 08:12:29.386936 2020] [wsgi:error] [pid 2326] [client 39.57.186.42:58605]   File "/var/www/FlaskApp/flaskapp.wsgi", line 7, in <module>
[Tue Mar 31 08:12:29.386951 2020] [wsgi:error] [pid 2326] [client 39.57.186.42:58605]     from FlaskApp import app as application
[Tue Mar 31 08:12:29.386973 2020] [wsgi:error] [pid 2326] [client 39.57.186.42:58605]   File "/var/www/FlaskApp/FlaskApp/__init__.py", line 31, in <module>
[Tue Mar 31 08:12:29.386986 2020] [wsgi:error] [pid 2326] [client 39.57.186.42:58605]     os.makedirs('organizations')
[Tue Mar 31 08:12:29.387006 2020] [wsgi:error] [pid 2326] [client 39.57.186.42:58605]   File "/usr/lib/python3.5/os.py", line 241, in makedirs
[Tue Mar 31 08:12:29.387018 2020] [wsgi:error] [pid 2326] [client 39.57.186.42:58605]     mkdir(name, mode)
[Tue Mar 31 08:12:29.387064 2020] [wsgi:error] [pid 2326] [client 39.57.186.42:58605] PermissionError: [Errno 13] Permission denied: 'organizations'
[Tue Mar 31 08:12:32.439022 2020] [wsgi:error] [pid 2328] [client 39.57.186.42:58607] mod_wsgi (pid=2328): Target WSGI script '/var/www/FlaskApp/flaskapp.wsgi' cannot be loaded as Python module.
[Tue Mar 31 08:12:32.439176 2020] [wsgi:error] [pid 2328] [client 39.57.186.42:58607] mod_wsgi (pid=2328): Exception occurred processing WSGI script '/var/www/FlaskApp/flaskapp.wsgi'.
[Tue Mar 31 08:12:32.440571 2020] [wsgi:error] [pid 2328] [client 39.57.186.42:58607] Traceback (most recent call last):
[Tue Mar 31 08:12:32.440638 2020] [wsgi:error] [pid 2328] [client 39.57.186.42:58607]   File "/var/www/FlaskApp/flaskapp.wsgi", line 7, in <module>
[Tue Mar 31 08:12:32.440653 2020] [wsgi:error] [pid 2328] [client 39.57.186.42:58607]     from FlaskApp import app as application
[Tue Mar 31 08:12:32.440675 2020] [wsgi:error] [pid 2328] [client 39.57.186.42:58607]   File "/var/www/FlaskApp/FlaskApp/__init__.py", line 31, in <module>
[Tue Mar 31 08:12:32.440688 2020] [wsgi:error] [pid 2328] [client 39.57.186.42:58607]     os.makedirs('organizations')
[Tue Mar 31 08:12:32.440708 2020] [wsgi:error] [pid 2328] [client 39.57.186.42:58607]   File "/usr/lib/python3.5/os.py", line 241, in makedirs
[Tue Mar 31 08:12:32.440720 2020] [wsgi:error] [pid 2328] [client 39.57.186.42:58607]     mkdir(name, mode)
[Tue Mar 31 08:12:32.440784 2020] [wsgi:error] [pid 2328] [client 39.57.186.42:58607] PermissionError: [Errno 13] Permission denied: 'organizations'
